============================
[debug] Begin to login ...

[error] :.:.:.:.: Except return :.:.:.:.:
[error] Python Error: 
 Traceback (most recent call last):
  File "/opt/hostedtoolcache/Python/3.8.7/x64/lib/python3.8/site-packages/urllib3/connectionpool.py", line 699, in urlopen
    httplib_response = self._make_request(
  File "/opt/hostedtoolcache/Python/3.8.7/x64/lib/python3.8/site-packages/urllib3/connectionpool.py", line 445, in _make_request
    six.raise_from(e, None)
  File "<string>", line 3, in raise_from
  File "/opt/hostedtoolcache/Python/3.8.7/x64/lib/python3.8/site-packages/urllib3/connectionpool.py", line 440, in _make_request
    httplib_response = conn.getresponse()
  File "/opt/hostedtoolcache/Python/3.8.7/x64/lib/python3.8/http/client.py", line 1347, in getresponse
    response.begin()
  File "/opt/hostedtoolcache/Python/3.8.7/x64/lib/python3.8/http/client.py", line 307, in begin
    version, status, reason = self._read_status()
  File "/opt/hostedtoolcache/Python/3.8.7/x64/lib/python3.8/http/client.py", line 268, in _read_status
    line = str(self.fp.readline(_MAXLINE + 1), "iso-8859-1")
  File "/opt/hostedtoolcache/Python/3.8.7/x64/lib/python3.8/socket.py", line 669, in readinto
    return self._sock.recv_into(b)
ConnectionResetError: [Errno 104] Connection reset by peer

During handling of the above exception, another exception occurred:

Traceback (most recent call last):
  File "/opt/hostedtoolcache/Python/3.8.7/x64/lib/python3.8/site-packages/requests/adapters.py", line 439, in send
    resp = conn.urlopen(
  File "/opt/hostedtoolcache/Python/3.8.7/x64/lib/python3.8/site-packages/urllib3/connectionpool.py", line 755, in urlopen
    retries = retries.increment(
  File "/opt/hostedtoolcache/Python/3.8.7/x64/lib/python3.8/site-packages/urllib3/util/retry.py", line 531, in increment
    raise six.reraise(type(error), error, _stacktrace)
  File "/opt/hostedtoolcache/Python/3.8.7/x64/lib/python3.8/site-packages/urllib3/packages/six.py", line 734, in reraise
    raise value.with_traceback(tb)
  File "/opt/hostedtoolcache/Python/3.8.7/x64/lib/python3.8/site-packages/urllib3/connectionpool.py", line 699, in urlopen
    httplib_response = self._make_request(
  File "/opt/hostedtoolcache/Python/3.8.7/x64/lib/python3.8/site-packages/urllib3/connectionpool.py", line 445, in _make_request
    six.raise_from(e, None)
  File "<string>", line 3, in raise_from
  File "/opt/hostedtoolcache/Python/3.8.7/x64/lib/python3.8/site-packages/urllib3/connectionpool.py", line 440, in _make_request
    httplib_response = conn.getresponse()
  File "/opt/hostedtoolcache/Python/3.8.7/x64/lib/python3.8/http/client.py", line 1347, in getresponse
    response.begin()
  File "/opt/hostedtoolcache/Python/3.8.7/x64/lib/python3.8/http/client.py", line 307, in begin
    version, status, reason = self._read_status()
  File "/opt/hostedtoolcache/Python/3.8.7/x64/lib/python3.8/http/client.py", line 268, in _read_status
    line = str(self.fp.readline(_MAXLINE + 1), "iso-8859-1")
  File "/opt/hostedtoolcache/Python/3.8.7/x64/lib/python3.8/socket.py", line 669, in readinto
    return self._sock.recv_into(b)
urllib3.exceptions.ProtocolError: ('Connection aborted.', ConnectionResetError(104, 'Connection reset by peer'))

During handling of the above exception, another exception occurred:

Traceback (most recent call last):
  File "Actions/checkin.py", line 69, in <module>
    response302 = sesh.post(req.url, data=user_form, headers=headers)
  File "/opt/hostedtoolcache/Python/3.8.7/x64/lib/python3.8/site-packages/requests/sessions.py", line 590, in post
    return self.request('POST', url, data=data, json=json, **kwargs)
  File "/opt/hostedtoolcache/Python/3.8.7/x64/lib/python3.8/site-packages/requests/sessions.py", line 542, in request
    resp = self.send(prep, **send_kwargs)
  File "/opt/hostedtoolcache/Python/3.8.7/x64/lib/python3.8/site-packages/requests/sessions.py", line 677, in send
    history = [resp for resp in gen]
  File "/opt/hostedtoolcache/Python/3.8.7/x64/lib/python3.8/site-packages/requests/sessions.py", line 677, in <listcomp>
    history = [resp for resp in gen]
  File "/opt/hostedtoolcache/Python/3.8.7/x64/lib/python3.8/site-packages/requests/sessions.py", line 237, in resolve_redirects
    resp = self.send(
  File "/opt/hostedtoolcache/Python/3.8.7/x64/lib/python3.8/site-packages/requests/sessions.py", line 655, in send
    r = adapter.send(request, **kwargs)
  File "/opt/hostedtoolcache/Python/3.8.7/x64/lib/python3.8/site-packages/requests/adapters.py", line 498, in send
    raise ConnectionError(err, request=request)
requests.exceptions.ConnectionError: ('Connection aborted.', ConnectionResetError(104, 'Connection reset by peer'))

[info] Task Finished at 2021-01-14 16:45:53 Thursday
============================

============================
[debug] Begin to login ...

[error] :.:.:.:.: Except return :.:.:.:.:
[error] Python Error: 
 Traceback (most recent call last):
  File "/opt/hostedtoolcache/Python/3.8.7/x64/lib/python3.8/site-packages/urllib3/connectionpool.py", line 699, in urlopen
    httplib_response = self._make_request(
  File "/opt/hostedtoolcache/Python/3.8.7/x64/lib/python3.8/site-packages/urllib3/connectionpool.py", line 445, in _make_request
    six.raise_from(e, None)
  File "<string>", line 3, in raise_from
  File "/opt/hostedtoolcache/Python/3.8.7/x64/lib/python3.8/site-packages/urllib3/connectionpool.py", line 440, in _make_request
    httplib_response = conn.getresponse()
  File "/opt/hostedtoolcache/Python/3.8.7/x64/lib/python3.8/http/client.py", line 1347, in getresponse
    response.begin()
  File "/opt/hostedtoolcache/Python/3.8.7/x64/lib/python3.8/http/client.py", line 307, in begin
    version, status, reason = self._read_status()
  File "/opt/hostedtoolcache/Python/3.8.7/x64/lib/python3.8/http/client.py", line 268, in _read_status
    line = str(self.fp.readline(_MAXLINE + 1), "iso-8859-1")
  File "/opt/hostedtoolcache/Python/3.8.7/x64/lib/python3.8/socket.py", line 669, in readinto
    return self._sock.recv_into(b)
ConnectionResetError: [Errno 104] Connection reset by peer

During handling of the above exception, another exception occurred:

Traceback (most recent call last):
  File "/opt/hostedtoolcache/Python/3.8.7/x64/lib/python3.8/site-packages/requests/adapters.py", line 439, in send
    resp = conn.urlopen(
  File "/opt/hostedtoolcache/Python/3.8.7/x64/lib/python3.8/site-packages/urllib3/connectionpool.py", line 755, in urlopen
    retries = retries.increment(
  File "/opt/hostedtoolcache/Python/3.8.7/x64/lib/python3.8/site-packages/urllib3/util/retry.py", line 531, in increment
    raise six.reraise(type(error), error, _stacktrace)
  File "/opt/hostedtoolcache/Python/3.8.7/x64/lib/python3.8/site-packages/urllib3/packages/six.py", line 734, in reraise
    raise value.with_traceback(tb)
  File "/opt/hostedtoolcache/Python/3.8.7/x64/lib/python3.8/site-packages/urllib3/connectionpool.py", line 699, in urlopen
    httplib_response = self._make_request(
  File "/opt/hostedtoolcache/Python/3.8.7/x64/lib/python3.8/site-packages/urllib3/connectionpool.py", line 445, in _make_request
    six.raise_from(e, None)
  File "<string>", line 3, in raise_from
  File "/opt/hostedtoolcache/Python/3.8.7/x64/lib/python3.8/site-packages/urllib3/connectionpool.py", line 440, in _make_request
    httplib_response = conn.getresponse()
  File "/opt/hostedtoolcache/Python/3.8.7/x64/lib/python3.8/http/client.py", line 1347, in getresponse
    response.begin()
  File "/opt/hostedtoolcache/Python/3.8.7/x64/lib/python3.8/http/client.py", line 307, in begin
    version, status, reason = self._read_status()
  File "/opt/hostedtoolcache/Python/3.8.7/x64/lib/python3.8/http/client.py", line 268, in _read_status
    line = str(self.fp.readline(_MAXLINE + 1), "iso-8859-1")
  File "/opt/hostedtoolcache/Python/3.8.7/x64/lib/python3.8/socket.py", line 669, in readinto
    return self._sock.recv_into(b)
urllib3.exceptions.ProtocolError: ('Connection aborted.', ConnectionResetError(104, 'Connection reset by peer'))

During handling of the above exception, another exception occurred:

Traceback (most recent call last):
  File "Actions/checkin.py", line 69, in <module>
    response302 = sesh.post(req.url, data=user_form, headers=headers)
  File "/opt/hostedtoolcache/Python/3.8.7/x64/lib/python3.8/site-packages/requests/sessions.py", line 590, in post
    return self.request('POST', url, data=data, json=json, **kwargs)
  File "/opt/hostedtoolcache/Python/3.8.7/x64/lib/python3.8/site-packages/requests/sessions.py", line 542, in request
    resp = self.send(prep, **send_kwargs)
  File "/opt/hostedtoolcache/Python/3.8.7/x64/lib/python3.8/site-packages/requests/sessions.py", line 677, in send
    history = [resp for resp in gen]
  File "/opt/hostedtoolcache/Python/3.8.7/x64/lib/python3.8/site-packages/requests/sessions.py", line 677, in <listcomp>
    history = [resp for resp in gen]
  File "/opt/hostedtoolcache/Python/3.8.7/x64/lib/python3.8/site-packages/requests/sessions.py", line 237, in resolve_redirects
    resp = self.send(
  File "/opt/hostedtoolcache/Python/3.8.7/x64/lib/python3.8/site-packages/requests/sessions.py", line 655, in send
    r = adapter.send(request, **kwargs)
  File "/opt/hostedtoolcache/Python/3.8.7/x64/lib/python3.8/site-packages/requests/adapters.py", line 498, in send
    raise ConnectionError(err, request=request)
requests.exceptions.ConnectionError: ('Connection aborted.', ConnectionResetError(104, 'Connection reset by peer'))

[info] Task Finished at 2021-01-14 20:01:38 Thursday
============================

============================
[debug] Begin to login ...

[error] :.:.:.:.: Except return :.:.:.:.:
[error] Python Error: 
 Traceback (most recent call last):
  File "/opt/hostedtoolcache/Python/3.8.7/x64/lib/python3.8/site-packages/urllib3/connectionpool.py", line 699, in urlopen
    httplib_response = self._make_request(
  File "/opt/hostedtoolcache/Python/3.8.7/x64/lib/python3.8/site-packages/urllib3/connectionpool.py", line 445, in _make_request
    six.raise_from(e, None)
  File "<string>", line 3, in raise_from
  File "/opt/hostedtoolcache/Python/3.8.7/x64/lib/python3.8/site-packages/urllib3/connectionpool.py", line 440, in _make_request
    httplib_response = conn.getresponse()
  File "/opt/hostedtoolcache/Python/3.8.7/x64/lib/python3.8/http/client.py", line 1347, in getresponse
    response.begin()
  File "/opt/hostedtoolcache/Python/3.8.7/x64/lib/python3.8/http/client.py", line 307, in begin
    version, status, reason = self._read_status()
  File "/opt/hostedtoolcache/Python/3.8.7/x64/lib/python3.8/http/client.py", line 268, in _read_status
    line = str(self.fp.readline(_MAXLINE + 1), "iso-8859-1")
  File "/opt/hostedtoolcache/Python/3.8.7/x64/lib/python3.8/socket.py", line 669, in readinto
    return self._sock.recv_into(b)
ConnectionResetError: [Errno 104] Connection reset by peer

During handling of the above exception, another exception occurred:

Traceback (most recent call last):
  File "/opt/hostedtoolcache/Python/3.8.7/x64/lib/python3.8/site-packages/requests/adapters.py", line 439, in send
    resp = conn.urlopen(
  File "/opt/hostedtoolcache/Python/3.8.7/x64/lib/python3.8/site-packages/urllib3/connectionpool.py", line 755, in urlopen
    retries = retries.increment(
  File "/opt/hostedtoolcache/Python/3.8.7/x64/lib/python3.8/site-packages/urllib3/util/retry.py", line 531, in increment
    raise six.reraise(type(error), error, _stacktrace)
  File "/opt/hostedtoolcache/Python/3.8.7/x64/lib/python3.8/site-packages/urllib3/packages/six.py", line 734, in reraise
    raise value.with_traceback(tb)
  File "/opt/hostedtoolcache/Python/3.8.7/x64/lib/python3.8/site-packages/urllib3/connectionpool.py", line 699, in urlopen
    httplib_response = self._make_request(
  File "/opt/hostedtoolcache/Python/3.8.7/x64/lib/python3.8/site-packages/urllib3/connectionpool.py", line 445, in _make_request
    six.raise_from(e, None)
  File "<string>", line 3, in raise_from
  File "/opt/hostedtoolcache/Python/3.8.7/x64/lib/python3.8/site-packages/urllib3/connectionpool.py", line 440, in _make_request
    httplib_response = conn.getresponse()
  File "/opt/hostedtoolcache/Python/3.8.7/x64/lib/python3.8/http/client.py", line 1347, in getresponse
    response.begin()
  File "/opt/hostedtoolcache/Python/3.8.7/x64/lib/python3.8/http/client.py", line 307, in begin
    version, status, reason = self._read_status()
  File "/opt/hostedtoolcache/Python/3.8.7/x64/lib/python3.8/http/client.py", line 268, in _read_status
    line = str(self.fp.readline(_MAXLINE + 1), "iso-8859-1")
  File "/opt/hostedtoolcache/Python/3.8.7/x64/lib/python3.8/socket.py", line 669, in readinto
    return self._sock.recv_into(b)
urllib3.exceptions.ProtocolError: ('Connection aborted.', ConnectionResetError(104, 'Connection reset by peer'))

During handling of the above exception, another exception occurred:

Traceback (most recent call last):
  File "Actions/checkin.py", line 69, in <module>
    response302 = sesh.post(req.url, data=user_form, headers=headers)
  File "/opt/hostedtoolcache/Python/3.8.7/x64/lib/python3.8/site-packages/requests/sessions.py", line 590, in post
    return self.request('POST', url, data=data, json=json, **kwargs)
  File "/opt/hostedtoolcache/Python/3.8.7/x64/lib/python3.8/site-packages/requests/sessions.py", line 542, in request
    resp = self.send(prep, **send_kwargs)
  File "/opt/hostedtoolcache/Python/3.8.7/x64/lib/python3.8/site-packages/requests/sessions.py", line 677, in send
    history = [resp for resp in gen]
  File "/opt/hostedtoolcache/Python/3.8.7/x64/lib/python3.8/site-packages/requests/sessions.py", line 677, in <listcomp>
    history = [resp for resp in gen]
  File "/opt/hostedtoolcache/Python/3.8.7/x64/lib/python3.8/site-packages/requests/sessions.py", line 237, in resolve_redirects
    resp = self.send(
  File "/opt/hostedtoolcache/Python/3.8.7/x64/lib/python3.8/site-packages/requests/sessions.py", line 655, in send
    r = adapter.send(request, **kwargs)
  File "/opt/hostedtoolcache/Python/3.8.7/x64/lib/python3.8/site-packages/requests/adapters.py", line 498, in send
    raise ConnectionError(err, request=request)
requests.exceptions.ConnectionError: ('Connection aborted.', ConnectionResetError(104, 'Connection reset by peer'))

[info] Task Finished at 2021-01-15 07:34:11 Friday
============================

============================
[debug] Begin to login ...

[error] :.:.:.:.: Except return :.:.:.:.:
[error] Python Error: 
 Traceback (most recent call last):
  File "/opt/hostedtoolcache/Python/3.8.7/x64/lib/python3.8/site-packages/urllib3/connectionpool.py", line 699, in urlopen
    httplib_response = self._make_request(
  File "/opt/hostedtoolcache/Python/3.8.7/x64/lib/python3.8/site-packages/urllib3/connectionpool.py", line 445, in _make_request
    six.raise_from(e, None)
  File "<string>", line 3, in raise_from
  File "/opt/hostedtoolcache/Python/3.8.7/x64/lib/python3.8/site-packages/urllib3/connectionpool.py", line 440, in _make_request
    httplib_response = conn.getresponse()
  File "/opt/hostedtoolcache/Python/3.8.7/x64/lib/python3.8/http/client.py", line 1347, in getresponse
    response.begin()
  File "/opt/hostedtoolcache/Python/3.8.7/x64/lib/python3.8/http/client.py", line 307, in begin
    version, status, reason = self._read_status()
  File "/opt/hostedtoolcache/Python/3.8.7/x64/lib/python3.8/http/client.py", line 268, in _read_status
    line = str(self.fp.readline(_MAXLINE + 1), "iso-8859-1")
  File "/opt/hostedtoolcache/Python/3.8.7/x64/lib/python3.8/socket.py", line 669, in readinto
    return self._sock.recv_into(b)
ConnectionResetError: [Errno 104] Connection reset by peer

During handling of the above exception, another exception occurred:

Traceback (most recent call last):
  File "/opt/hostedtoolcache/Python/3.8.7/x64/lib/python3.8/site-packages/requests/adapters.py", line 439, in send
    resp = conn.urlopen(
  File "/opt/hostedtoolcache/Python/3.8.7/x64/lib/python3.8/site-packages/urllib3/connectionpool.py", line 755, in urlopen
    retries = retries.increment(
  File "/opt/hostedtoolcache/Python/3.8.7/x64/lib/python3.8/site-packages/urllib3/util/retry.py", line 531, in increment
    raise six.reraise(type(error), error, _stacktrace)
  File "/opt/hostedtoolcache/Python/3.8.7/x64/lib/python3.8/site-packages/urllib3/packages/six.py", line 734, in reraise
    raise value.with_traceback(tb)
  File "/opt/hostedtoolcache/Python/3.8.7/x64/lib/python3.8/site-packages/urllib3/connectionpool.py", line 699, in urlopen
    httplib_response = self._make_request(
  File "/opt/hostedtoolcache/Python/3.8.7/x64/lib/python3.8/site-packages/urllib3/connectionpool.py", line 445, in _make_request
    six.raise_from(e, None)
  File "<string>", line 3, in raise_from
  File "/opt/hostedtoolcache/Python/3.8.7/x64/lib/python3.8/site-packages/urllib3/connectionpool.py", line 440, in _make_request
    httplib_response = conn.getresponse()
  File "/opt/hostedtoolcache/Python/3.8.7/x64/lib/python3.8/http/client.py", line 1347, in getresponse
    response.begin()
  File "/opt/hostedtoolcache/Python/3.8.7/x64/lib/python3.8/http/client.py", line 307, in begin
    version, status, reason = self._read_status()
  File "/opt/hostedtoolcache/Python/3.8.7/x64/lib/python3.8/http/client.py", line 268, in _read_status
    line = str(self.fp.readline(_MAXLINE + 1), "iso-8859-1")
  File "/opt/hostedtoolcache/Python/3.8.7/x64/lib/python3.8/socket.py", line 669, in readinto
    return self._sock.recv_into(b)
urllib3.exceptions.ProtocolError: ('Connection aborted.', ConnectionResetError(104, 'Connection reset by peer'))

During handling of the above exception, another exception occurred:

Traceback (most recent call last):
  File "Actions/checkin.py", line 69, in <module>
    response302 = sesh.post(req.url, data=user_form, headers=headers)
  File "/opt/hostedtoolcache/Python/3.8.7/x64/lib/python3.8/site-packages/requests/sessions.py", line 590, in post
    return self.request('POST', url, data=data, json=json, **kwargs)
  File "/opt/hostedtoolcache/Python/3.8.7/x64/lib/python3.8/site-packages/requests/sessions.py", line 542, in request
    resp = self.send(prep, **send_kwargs)
  File "/opt/hostedtoolcache/Python/3.8.7/x64/lib/python3.8/site-packages/requests/sessions.py", line 677, in send
    history = [resp for resp in gen]
  File "/opt/hostedtoolcache/Python/3.8.7/x64/lib/python3.8/site-packages/requests/sessions.py", line 677, in <listcomp>
    history = [resp for resp in gen]
  File "/opt/hostedtoolcache/Python/3.8.7/x64/lib/python3.8/site-packages/requests/sessions.py", line 237, in resolve_redirects
    resp = self.send(
  File "/opt/hostedtoolcache/Python/3.8.7/x64/lib/python3.8/site-packages/requests/sessions.py", line 655, in send
    r = adapter.send(request, **kwargs)
  File "/opt/hostedtoolcache/Python/3.8.7/x64/lib/python3.8/site-packages/requests/adapters.py", line 498, in send
    raise ConnectionError(err, request=request)
requests.exceptions.ConnectionError: ('Connection aborted.', ConnectionResetError(104, 'Connection reset by peer'))

[info] Task Finished at 2021-01-15 08:54:17 Friday
============================

============================
[debug] Begin to login ...

[error] :.:.:.:.: Except return :.:.:.:.:
[error] Python Error: 
 Traceback (most recent call last):
  File "/opt/hostedtoolcache/Python/3.8.7/x64/lib/python3.8/site-packages/urllib3/connectionpool.py", line 699, in urlopen
    httplib_response = self._make_request(
  File "/opt/hostedtoolcache/Python/3.8.7/x64/lib/python3.8/site-packages/urllib3/connectionpool.py", line 445, in _make_request
    six.raise_from(e, None)
  File "<string>", line 3, in raise_from
  File "/opt/hostedtoolcache/Python/3.8.7/x64/lib/python3.8/site-packages/urllib3/connectionpool.py", line 440, in _make_request
    httplib_response = conn.getresponse()
  File "/opt/hostedtoolcache/Python/3.8.7/x64/lib/python3.8/http/client.py", line 1347, in getresponse
    response.begin()
  File "/opt/hostedtoolcache/Python/3.8.7/x64/lib/python3.8/http/client.py", line 307, in begin
    version, status, reason = self._read_status()
  File "/opt/hostedtoolcache/Python/3.8.7/x64/lib/python3.8/http/client.py", line 268, in _read_status
    line = str(self.fp.readline(_MAXLINE + 1), "iso-8859-1")
  File "/opt/hostedtoolcache/Python/3.8.7/x64/lib/python3.8/socket.py", line 669, in readinto
    return self._sock.recv_into(b)
ConnectionResetError: [Errno 104] Connection reset by peer

During handling of the above exception, another exception occurred:

Traceback (most recent call last):
  File "/opt/hostedtoolcache/Python/3.8.7/x64/lib/python3.8/site-packages/requests/adapters.py", line 439, in send
    resp = conn.urlopen(
  File "/opt/hostedtoolcache/Python/3.8.7/x64/lib/python3.8/site-packages/urllib3/connectionpool.py", line 755, in urlopen
    retries = retries.increment(
  File "/opt/hostedtoolcache/Python/3.8.7/x64/lib/python3.8/site-packages/urllib3/util/retry.py", line 531, in increment
    raise six.reraise(type(error), error, _stacktrace)
  File "/opt/hostedtoolcache/Python/3.8.7/x64/lib/python3.8/site-packages/urllib3/packages/six.py", line 734, in reraise
    raise value.with_traceback(tb)
  File "/opt/hostedtoolcache/Python/3.8.7/x64/lib/python3.8/site-packages/urllib3/connectionpool.py", line 699, in urlopen
    httplib_response = self._make_request(
  File "/opt/hostedtoolcache/Python/3.8.7/x64/lib/python3.8/site-packages/urllib3/connectionpool.py", line 445, in _make_request
    six.raise_from(e, None)
  File "<string>", line 3, in raise_from
  File "/opt/hostedtoolcache/Python/3.8.7/x64/lib/python3.8/site-packages/urllib3/connectionpool.py", line 440, in _make_request
    httplib_response = conn.getresponse()
  File "/opt/hostedtoolcache/Python/3.8.7/x64/lib/python3.8/http/client.py", line 1347, in getresponse
    response.begin()
  File "/opt/hostedtoolcache/Python/3.8.7/x64/lib/python3.8/http/client.py", line 307, in begin
    version, status, reason = self._read_status()
  File "/opt/hostedtoolcache/Python/3.8.7/x64/lib/python3.8/http/client.py", line 268, in _read_status
    line = str(self.fp.readline(_MAXLINE + 1), "iso-8859-1")
  File "/opt/hostedtoolcache/Python/3.8.7/x64/lib/python3.8/socket.py", line 669, in readinto
    return self._sock.recv_into(b)
urllib3.exceptions.ProtocolError: ('Connection aborted.', ConnectionResetError(104, 'Connection reset by peer'))

During handling of the above exception, another exception occurred:

Traceback (most recent call last):
  File "Actions/checkin.py", line 69, in <module>
    response302 = sesh.post(req.url, data=user_form, headers=headers)
  File "/opt/hostedtoolcache/Python/3.8.7/x64/lib/python3.8/site-packages/requests/sessions.py", line 590, in post
    return self.request('POST', url, data=data, json=json, **kwargs)
  File "/opt/hostedtoolcache/Python/3.8.7/x64/lib/python3.8/site-packages/requests/sessions.py", line 542, in request
    resp = self.send(prep, **send_kwargs)
  File "/opt/hostedtoolcache/Python/3.8.7/x64/lib/python3.8/site-packages/requests/sessions.py", line 677, in send
    history = [resp for resp in gen]
  File "/opt/hostedtoolcache/Python/3.8.7/x64/lib/python3.8/site-packages/requests/sessions.py", line 677, in <listcomp>
    history = [resp for resp in gen]
  File "/opt/hostedtoolcache/Python/3.8.7/x64/lib/python3.8/site-packages/requests/sessions.py", line 237, in resolve_redirects
    resp = self.send(
  File "/opt/hostedtoolcache/Python/3.8.7/x64/lib/python3.8/site-packages/requests/sessions.py", line 655, in send
    r = adapter.send(request, **kwargs)
  File "/opt/hostedtoolcache/Python/3.8.7/x64/lib/python3.8/site-packages/requests/adapters.py", line 498, in send
    raise ConnectionError(err, request=request)
requests.exceptions.ConnectionError: ('Connection aborted.', ConnectionResetError(104, 'Connection reset by peer'))

[info] Task Finished at 2021-01-15 10:39:43 Friday
============================

============================
[debug] Begin to login ...

[error] :.:.:.:.: Except return :.:.:.:.:
[error] Python Error: 
 Traceback (most recent call last):
  File "/opt/hostedtoolcache/Python/3.8.7/x64/lib/python3.8/site-packages/urllib3/connectionpool.py", line 699, in urlopen
    httplib_response = self._make_request(
  File "/opt/hostedtoolcache/Python/3.8.7/x64/lib/python3.8/site-packages/urllib3/connectionpool.py", line 445, in _make_request
    six.raise_from(e, None)
  File "<string>", line 3, in raise_from
  File "/opt/hostedtoolcache/Python/3.8.7/x64/lib/python3.8/site-packages/urllib3/connectionpool.py", line 440, in _make_request
    httplib_response = conn.getresponse()
  File "/opt/hostedtoolcache/Python/3.8.7/x64/lib/python3.8/http/client.py", line 1347, in getresponse
    response.begin()
  File "/opt/hostedtoolcache/Python/3.8.7/x64/lib/python3.8/http/client.py", line 307, in begin
    version, status, reason = self._read_status()
  File "/opt/hostedtoolcache/Python/3.8.7/x64/lib/python3.8/http/client.py", line 268, in _read_status
    line = str(self.fp.readline(_MAXLINE + 1), "iso-8859-1")
  File "/opt/hostedtoolcache/Python/3.8.7/x64/lib/python3.8/socket.py", line 669, in readinto
    return self._sock.recv_into(b)
ConnectionResetError: [Errno 104] Connection reset by peer

During handling of the above exception, another exception occurred:

Traceback (most recent call last):
  File "/opt/hostedtoolcache/Python/3.8.7/x64/lib/python3.8/site-packages/requests/adapters.py", line 439, in send
    resp = conn.urlopen(
  File "/opt/hostedtoolcache/Python/3.8.7/x64/lib/python3.8/site-packages/urllib3/connectionpool.py", line 755, in urlopen
    retries = retries.increment(
  File "/opt/hostedtoolcache/Python/3.8.7/x64/lib/python3.8/site-packages/urllib3/util/retry.py", line 531, in increment
    raise six.reraise(type(error), error, _stacktrace)
  File "/opt/hostedtoolcache/Python/3.8.7/x64/lib/python3.8/site-packages/urllib3/packages/six.py", line 734, in reraise
    raise value.with_traceback(tb)
  File "/opt/hostedtoolcache/Python/3.8.7/x64/lib/python3.8/site-packages/urllib3/connectionpool.py", line 699, in urlopen
    httplib_response = self._make_request(
  File "/opt/hostedtoolcache/Python/3.8.7/x64/lib/python3.8/site-packages/urllib3/connectionpool.py", line 445, in _make_request
    six.raise_from(e, None)
  File "<string>", line 3, in raise_from
  File "/opt/hostedtoolcache/Python/3.8.7/x64/lib/python3.8/site-packages/urllib3/connectionpool.py", line 440, in _make_request
    httplib_response = conn.getresponse()
  File "/opt/hostedtoolcache/Python/3.8.7/x64/lib/python3.8/http/client.py", line 1347, in getresponse
    response.begin()
  File "/opt/hostedtoolcache/Python/3.8.7/x64/lib/python3.8/http/client.py", line 307, in begin
    version, status, reason = self._read_status()
  File "/opt/hostedtoolcache/Python/3.8.7/x64/lib/python3.8/http/client.py", line 268, in _read_status
    line = str(self.fp.readline(_MAXLINE + 1), "iso-8859-1")
  File "/opt/hostedtoolcache/Python/3.8.7/x64/lib/python3.8/socket.py", line 669, in readinto
    return self._sock.recv_into(b)
urllib3.exceptions.ProtocolError: ('Connection aborted.', ConnectionResetError(104, 'Connection reset by peer'))

During handling of the above exception, another exception occurred:

Traceback (most recent call last):
  File "Actions/checkin.py", line 69, in <module>
    response302 = sesh.post(req.url, data=user_form, headers=headers)
  File "/opt/hostedtoolcache/Python/3.8.7/x64/lib/python3.8/site-packages/requests/sessions.py", line 590, in post
    return self.request('POST', url, data=data, json=json, **kwargs)
  File "/opt/hostedtoolcache/Python/3.8.7/x64/lib/python3.8/site-packages/requests/sessions.py", line 542, in request
    resp = self.send(prep, **send_kwargs)
  File "/opt/hostedtoolcache/Python/3.8.7/x64/lib/python3.8/site-packages/requests/sessions.py", line 677, in send
    history = [resp for resp in gen]
  File "/opt/hostedtoolcache/Python/3.8.7/x64/lib/python3.8/site-packages/requests/sessions.py", line 677, in <listcomp>
    history = [resp for resp in gen]
  File "/opt/hostedtoolcache/Python/3.8.7/x64/lib/python3.8/site-packages/requests/sessions.py", line 237, in resolve_redirects
    resp = self.send(
  File "/opt/hostedtoolcache/Python/3.8.7/x64/lib/python3.8/site-packages/requests/sessions.py", line 655, in send
    r = adapter.send(request, **kwargs)
  File "/opt/hostedtoolcache/Python/3.8.7/x64/lib/python3.8/site-packages/requests/adapters.py", line 498, in send
    raise ConnectionError(err, request=request)
requests.exceptions.ConnectionError: ('Connection aborted.', ConnectionResetError(104, 'Connection reset by peer'))

[info] Task Finished at 2021-01-16 07:37:29 Saturday
============================

============================
[debug] Begin to login ...

[error] :.:.:.:.: Except return :.:.:.:.:
[error] Python Error: 
 Traceback (most recent call last):
  File "/opt/hostedtoolcache/Python/3.8.7/x64/lib/python3.8/site-packages/urllib3/connectionpool.py", line 699, in urlopen
    httplib_response = self._make_request(
  File "/opt/hostedtoolcache/Python/3.8.7/x64/lib/python3.8/site-packages/urllib3/connectionpool.py", line 445, in _make_request
    six.raise_from(e, None)
  File "<string>", line 3, in raise_from
  File "/opt/hostedtoolcache/Python/3.8.7/x64/lib/python3.8/site-packages/urllib3/connectionpool.py", line 440, in _make_request
    httplib_response = conn.getresponse()
  File "/opt/hostedtoolcache/Python/3.8.7/x64/lib/python3.8/http/client.py", line 1347, in getresponse
    response.begin()
  File "/opt/hostedtoolcache/Python/3.8.7/x64/lib/python3.8/http/client.py", line 307, in begin
    version, status, reason = self._read_status()
  File "/opt/hostedtoolcache/Python/3.8.7/x64/lib/python3.8/http/client.py", line 268, in _read_status
    line = str(self.fp.readline(_MAXLINE + 1), "iso-8859-1")
  File "/opt/hostedtoolcache/Python/3.8.7/x64/lib/python3.8/socket.py", line 669, in readinto
    return self._sock.recv_into(b)
ConnectionResetError: [Errno 104] Connection reset by peer

During handling of the above exception, another exception occurred:

Traceback (most recent call last):
  File "/opt/hostedtoolcache/Python/3.8.7/x64/lib/python3.8/site-packages/requests/adapters.py", line 439, in send
    resp = conn.urlopen(
  File "/opt/hostedtoolcache/Python/3.8.7/x64/lib/python3.8/site-packages/urllib3/connectionpool.py", line 755, in urlopen
    retries = retries.increment(
  File "/opt/hostedtoolcache/Python/3.8.7/x64/lib/python3.8/site-packages/urllib3/util/retry.py", line 531, in increment
    raise six.reraise(type(error), error, _stacktrace)
  File "/opt/hostedtoolcache/Python/3.8.7/x64/lib/python3.8/site-packages/urllib3/packages/six.py", line 734, in reraise
    raise value.with_traceback(tb)
  File "/opt/hostedtoolcache/Python/3.8.7/x64/lib/python3.8/site-packages/urllib3/connectionpool.py", line 699, in urlopen
    httplib_response = self._make_request(
  File "/opt/hostedtoolcache/Python/3.8.7/x64/lib/python3.8/site-packages/urllib3/connectionpool.py", line 445, in _make_request
    six.raise_from(e, None)
  File "<string>", line 3, in raise_from
  File "/opt/hostedtoolcache/Python/3.8.7/x64/lib/python3.8/site-packages/urllib3/connectionpool.py", line 440, in _make_request
    httplib_response = conn.getresponse()
  File "/opt/hostedtoolcache/Python/3.8.7/x64/lib/python3.8/http/client.py", line 1347, in getresponse
    response.begin()
  File "/opt/hostedtoolcache/Python/3.8.7/x64/lib/python3.8/http/client.py", line 307, in begin
    version, status, reason = self._read_status()
  File "/opt/hostedtoolcache/Python/3.8.7/x64/lib/python3.8/http/client.py", line 268, in _read_status
    line = str(self.fp.readline(_MAXLINE + 1), "iso-8859-1")
  File "/opt/hostedtoolcache/Python/3.8.7/x64/lib/python3.8/socket.py", line 669, in readinto
    return self._sock.recv_into(b)
urllib3.exceptions.ProtocolError: ('Connection aborted.', ConnectionResetError(104, 'Connection reset by peer'))

During handling of the above exception, another exception occurred:

Traceback (most recent call last):
  File "Actions/checkin.py", line 69, in <module>
    response302 = sesh.post(req.url, data=user_form, headers=headers)
  File "/opt/hostedtoolcache/Python/3.8.7/x64/lib/python3.8/site-packages/requests/sessions.py", line 590, in post
    return self.request('POST', url, data=data, json=json, **kwargs)
  File "/opt/hostedtoolcache/Python/3.8.7/x64/lib/python3.8/site-packages/requests/sessions.py", line 542, in request
    resp = self.send(prep, **send_kwargs)
  File "/opt/hostedtoolcache/Python/3.8.7/x64/lib/python3.8/site-packages/requests/sessions.py", line 677, in send
    history = [resp for resp in gen]
  File "/opt/hostedtoolcache/Python/3.8.7/x64/lib/python3.8/site-packages/requests/sessions.py", line 677, in <listcomp>
    history = [resp for resp in gen]
  File "/opt/hostedtoolcache/Python/3.8.7/x64/lib/python3.8/site-packages/requests/sessions.py", line 237, in resolve_redirects
    resp = self.send(
  File "/opt/hostedtoolcache/Python/3.8.7/x64/lib/python3.8/site-packages/requests/sessions.py", line 655, in send
    r = adapter.send(request, **kwargs)
  File "/opt/hostedtoolcache/Python/3.8.7/x64/lib/python3.8/site-packages/requests/adapters.py", line 498, in send
    raise ConnectionError(err, request=request)
requests.exceptions.ConnectionError: ('Connection aborted.', ConnectionResetError(104, 'Connection reset by peer'))

[info] Task Finished at 2021-01-16 08:56:55 Saturday
============================

============================
[debug] Begin to login ...

[error] :.:.:.:.: Except return :.:.:.:.:
[error] Python Error: 
 Traceback (most recent call last):
  File "/opt/hostedtoolcache/Python/3.8.7/x64/lib/python3.8/site-packages/urllib3/connectionpool.py", line 699, in urlopen
    httplib_response = self._make_request(
  File "/opt/hostedtoolcache/Python/3.8.7/x64/lib/python3.8/site-packages/urllib3/connectionpool.py", line 445, in _make_request
    six.raise_from(e, None)
  File "<string>", line 3, in raise_from
  File "/opt/hostedtoolcache/Python/3.8.7/x64/lib/python3.8/site-packages/urllib3/connectionpool.py", line 440, in _make_request
    httplib_response = conn.getresponse()
  File "/opt/hostedtoolcache/Python/3.8.7/x64/lib/python3.8/http/client.py", line 1347, in getresponse
    response.begin()
  File "/opt/hostedtoolcache/Python/3.8.7/x64/lib/python3.8/http/client.py", line 307, in begin
    version, status, reason = self._read_status()
  File "/opt/hostedtoolcache/Python/3.8.7/x64/lib/python3.8/http/client.py", line 268, in _read_status
    line = str(self.fp.readline(_MAXLINE + 1), "iso-8859-1")
  File "/opt/hostedtoolcache/Python/3.8.7/x64/lib/python3.8/socket.py", line 669, in readinto
    return self._sock.recv_into(b)
ConnectionResetError: [Errno 104] Connection reset by peer

During handling of the above exception, another exception occurred:

Traceback (most recent call last):
  File "/opt/hostedtoolcache/Python/3.8.7/x64/lib/python3.8/site-packages/requests/adapters.py", line 439, in send
    resp = conn.urlopen(
  File "/opt/hostedtoolcache/Python/3.8.7/x64/lib/python3.8/site-packages/urllib3/connectionpool.py", line 755, in urlopen
    retries = retries.increment(
  File "/opt/hostedtoolcache/Python/3.8.7/x64/lib/python3.8/site-packages/urllib3/util/retry.py", line 531, in increment
    raise six.reraise(type(error), error, _stacktrace)
  File "/opt/hostedtoolcache/Python/3.8.7/x64/lib/python3.8/site-packages/urllib3/packages/six.py", line 734, in reraise
    raise value.with_traceback(tb)
  File "/opt/hostedtoolcache/Python/3.8.7/x64/lib/python3.8/site-packages/urllib3/connectionpool.py", line 699, in urlopen
    httplib_response = self._make_request(
  File "/opt/hostedtoolcache/Python/3.8.7/x64/lib/python3.8/site-packages/urllib3/connectionpool.py", line 445, in _make_request
    six.raise_from(e, None)
  File "<string>", line 3, in raise_from
  File "/opt/hostedtoolcache/Python/3.8.7/x64/lib/python3.8/site-packages/urllib3/connectionpool.py", line 440, in _make_request
    httplib_response = conn.getresponse()
  File "/opt/hostedtoolcache/Python/3.8.7/x64/lib/python3.8/http/client.py", line 1347, in getresponse
    response.begin()
  File "/opt/hostedtoolcache/Python/3.8.7/x64/lib/python3.8/http/client.py", line 307, in begin
    version, status, reason = self._read_status()
  File "/opt/hostedtoolcache/Python/3.8.7/x64/lib/python3.8/http/client.py", line 268, in _read_status
    line = str(self.fp.readline(_MAXLINE + 1), "iso-8859-1")
  File "/opt/hostedtoolcache/Python/3.8.7/x64/lib/python3.8/socket.py", line 669, in readinto
    return self._sock.recv_into(b)
urllib3.exceptions.ProtocolError: ('Connection aborted.', ConnectionResetError(104, 'Connection reset by peer'))

During handling of the above exception, another exception occurred:

Traceback (most recent call last):
  File "Actions/checkin.py", line 69, in <module>
    response302 = sesh.post(req.url, data=user_form, headers=headers)
  File "/opt/hostedtoolcache/Python/3.8.7/x64/lib/python3.8/site-packages/requests/sessions.py", line 590, in post
    return self.request('POST', url, data=data, json=json, **kwargs)
  File "/opt/hostedtoolcache/Python/3.8.7/x64/lib/python3.8/site-packages/requests/sessions.py", line 542, in request
    resp = self.send(prep, **send_kwargs)
  File "/opt/hostedtoolcache/Python/3.8.7/x64/lib/python3.8/site-packages/requests/sessions.py", line 677, in send
    history = [resp for resp in gen]
  File "/opt/hostedtoolcache/Python/3.8.7/x64/lib/python3.8/site-packages/requests/sessions.py", line 677, in <listcomp>
    history = [resp for resp in gen]
  File "/opt/hostedtoolcache/Python/3.8.7/x64/lib/python3.8/site-packages/requests/sessions.py", line 237, in resolve_redirects
    resp = self.send(
  File "/opt/hostedtoolcache/Python/3.8.7/x64/lib/python3.8/site-packages/requests/sessions.py", line 655, in send
    r = adapter.send(request, **kwargs)
  File "/opt/hostedtoolcache/Python/3.8.7/x64/lib/python3.8/site-packages/requests/adapters.py", line 498, in send
    raise ConnectionError(err, request=request)
requests.exceptions.ConnectionError: ('Connection aborted.', ConnectionResetError(104, 'Connection reset by peer'))

[info] Task Finished at 2021-01-16 10:45:38 Saturday
============================

============================
[debug] Begin to login ...
[debug] Form url:  http://jkgc.hrbeu.edu.cn/infoplus/form/7910239/render
[debug] Form Status:  SUCCEED
[debug] Form stJson:  {'errno': 0, 'ecode': 'SUCCEED', 'entities': [{'stepId': 2, 'name': '办结', 'code': 'autoStep1', 'status': 0, 'type': 'Auto', 'flowStepId': 0, 'executorSelection': 0, 'timestamp': 0, 'posts': [], 'users': [], 'parallel': False, 'hasInstantNotification': False, 'hasCarbonCopy': False, 'entryId': 7841748, 'entryStatus': 0, 'entryRelease': False}]}
[info] Checkin succeed with jsoncode SUCCEED
:.:.:.:.: Finally :.:.:.:.:
[info] Notification sended at 2021-01-17 07:27:29 Sunday
[info] Task Finished at 2021-01-17 07:27:29 Sunday
============================

============================
[debug] Begin to login ...
[debug] Form url:  http://jkgc.hrbeu.edu.cn/infoplus/form/7917560/render
[debug] Form Status:  SUCCEED
[debug] Form stJson:  {'errno': 0, 'ecode': 'SUCCEED', 'entities': [{'stepId': 2, 'name': '办结', 'code': 'autoStep1', 'status': 0, 'type': 'Auto', 'flowStepId': 0, 'executorSelection': 0, 'timestamp': 0, 'posts': [], 'users': [], 'parallel': False, 'hasInstantNotification': False, 'hasCarbonCopy': False, 'entryId': 7849069, 'entryStatus': 0, 'entryRelease': False}]}
[info] Checkin succeed with jsoncode SUCCEED
:.:.:.:.: Finally :.:.:.:.:
[info] Notification sended at 2021-01-17 08:38:28 Sunday
[info] Task Finished at 2021-01-17 08:38:28 Sunday
============================

============================
[debug] Begin to login ...

[error] :.:.:.:.: Except return :.:.:.:.:
[error] Python Error: 
 Traceback (most recent call last):
  File "Actions/checkin.py", line 78, in <module>
    csrfToken = csrfToken.pop().attrib["content"]
IndexError: pop from empty list

:.:.:.:.: Finally :.:.:.:.:
[info] Notification sended at 2021-01-17 10:13:27 Sunday
[info] Task Finished at 2021-01-17 10:13:27 Sunday
============================

============================
[debug] Begin to login ...

[error] :.:.:.:.: Except return :.:.:.:.:
[error] Python Error: 
 Traceback (most recent call last):
  File "Actions/checkin.py", line 78, in <module>
    csrfToken = csrfToken.pop().attrib["content"]
IndexError: pop from empty list

:.:.:.:.: Finally :.:.:.:.:
[info] Notification sended at 2021-01-17 10:25:12 Sunday
[info] Task Finished at 2021-01-17 10:25:12 Sunday
============================

============================
[debug] Begin to login ...

[error] :.:.:.:.: Except return :.:.:.:.:
[error] Python Error: 
 Traceback (most recent call last):
  File "Actions/checkin.py", line 78, in <module>
    csrfToken = csrfToken.pop().attrib["content"]
IndexError: pop from empty list

:.:.:.:.: Finally :.:.:.:.:
[info] Notification sended at 2021-01-18 07:24:29 Monday
[info] Task Finished at 2021-01-18 07:24:29 Monday
============================

============================
[debug] Begin to login ...

[error] :.:.:.:.: Except return :.:.:.:.:
[error] Python Error: 
 Traceback (most recent call last):
  File "Actions/checkin.py", line 78, in <module>
    csrfToken = csrfToken.pop().attrib["content"]
IndexError: pop from empty list

:.:.:.:.: Finally :.:.:.:.:
[info] Notification sended at 2021-01-18 08:29:21 Monday
[info] Task Finished at 2021-01-18 08:29:21 Monday
============================

============================
[debug] Begin to login ...

[error] :.:.:.:.: Except return :.:.:.:.:
[error] Python Error: 
 Traceback (most recent call last):
  File "Actions/checkin.py", line 78, in <module>
    csrfToken = csrfToken.pop().attrib["content"]
IndexError: pop from empty list

:.:.:.:.: Finally :.:.:.:.:
[info] Notification sended at 2021-01-18 10:31:02 Monday
[info] Task Finished at 2021-01-18 10:31:02 Monday
============================

============================
[debug] Begin to login ...

[error] :.:.:.:.: Except return :.:.:.:.:
[error] Python Error: 
 Traceback (most recent call last):
  File "Actions/checkin.py", line 78, in <module>
    csrfToken = csrfToken.pop().attrib["content"]
IndexError: pop from empty list

:.:.:.:.: Finally :.:.:.:.:
[info] Notification sended at 2021-01-19 07:28:38 Tuesday
[info] Task Finished at 2021-01-19 07:28:38 Tuesday
============================

============================
[debug] Begin to login ...

[error] :.:.:.:.: Except return :.:.:.:.:
[error] Python Error: 
 Traceback (most recent call last):
  File "Actions/checkin.py", line 78, in <module>
    csrfToken = csrfToken.pop().attrib["content"]
IndexError: pop from empty list

:.:.:.:.: Finally :.:.:.:.:
[info] Notification sended at 2021-01-19 08:33:07 Tuesday
[info] Task Finished at 2021-01-19 08:33:07 Tuesday
============================

============================
[debug] Begin to login ...

[error] :.:.:.:.: Except return :.:.:.:.:
[error] Python Error: 
 Traceback (most recent call last):
  File "Actions/checkin.py", line 78, in <module>
    csrfToken = csrfToken.pop().attrib["content"]
IndexError: pop from empty list

:.:.:.:.: Finally :.:.:.:.:
[info] Notification sended at 2021-01-19 10:34:02 Tuesday
[info] Task Finished at 2021-01-19 10:34:02 Tuesday
============================

============================
[debug] Begin to login ...

[error] :.:.:.:.: Except return :.:.:.:.:
[error] Python Error: 
 Traceback (most recent call last):
  File "Actions/checkin.py", line 78, in <module>
    csrfToken = csrfToken.pop().attrib["content"]
IndexError: pop from empty list

:.:.:.:.: Finally :.:.:.:.:
[info] Notification sended at 2021-01-20 07:29:29 Wednesday
[info] Task Finished at 2021-01-20 07:29:29 Wednesday
============================

============================
[debug] Begin to login ...

[error] :.:.:.:.: Except return :.:.:.:.:
[error] Python Error: 
 Traceback (most recent call last):
  File "Actions/checkin.py", line 78, in <module>
    csrfToken = csrfToken.pop().attrib["content"]
IndexError: pop from empty list

:.:.:.:.: Finally :.:.:.:.:
[info] Notification sended at 2021-01-20 08:34:40 Wednesday
[info] Task Finished at 2021-01-20 08:34:40 Wednesday
============================

============================
[debug] Begin to login ...

[error] :.:.:.:.: Except return :.:.:.:.:
[error] Python Error: 
 Traceback (most recent call last):
  File "Actions/checkin.py", line 78, in <module>
    csrfToken = csrfToken.pop().attrib["content"]
IndexError: pop from empty list

:.:.:.:.: Finally :.:.:.:.:
[info] Notification sended at 2021-01-20 10:36:15 Wednesday
[info] Task Finished at 2021-01-20 10:36:15 Wednesday
============================

============================
[debug] Begin to login ...

[error] :.:.:.:.: Except return :.:.:.:.:
[error] Python Error: 
 Traceback (most recent call last):
  File "Actions/checkin.py", line 78, in <module>
    csrfToken = csrfToken.pop().attrib["content"]
IndexError: pop from empty list

:.:.:.:.: Finally :.:.:.:.:
[info] Notification sended at 2021-01-21 07:26:12 Thursday
[info] Task Finished at 2021-01-21 07:26:12 Thursday
============================

============================
[debug] Begin to login ...

[error] :.:.:.:.: Except return :.:.:.:.:
[error] Python Error: 
 Traceback (most recent call last):
  File "Actions/checkin.py", line 78, in <module>
    csrfToken = csrfToken.pop().attrib["content"]
IndexError: pop from empty list

:.:.:.:.: Finally :.:.:.:.:
[info] Notification sended at 2021-01-21 08:34:05 Thursday
[info] Task Finished at 2021-01-21 08:34:05 Thursday
============================

============================
[debug] Begin to login ...

[error] :.:.:.:.: Except return :.:.:.:.:
[error] Python Error: 
 Traceback (most recent call last):
  File "Actions/checkin.py", line 78, in <module>
    csrfToken = csrfToken.pop().attrib["content"]
IndexError: pop from empty list

:.:.:.:.: Finally :.:.:.:.:
[info] Notification sended at 2021-01-21 10:36:19 Thursday
[info] Task Finished at 2021-01-21 10:36:19 Thursday
============================

============================
[debug] Begin to login ...

[error] :.:.:.:.: Except return :.:.:.:.:
[error] Python Error: 
 Traceback (most recent call last):
  File "Actions/checkin.py", line 78, in <module>
    csrfToken = csrfToken.pop().attrib["content"]
IndexError: pop from empty list

:.:.:.:.: Finally :.:.:.:.:
[info] Notification sended at 2021-01-22 07:26:42 Friday
[info] Task Finished at 2021-01-22 07:26:42 Friday
============================

============================
[debug] Begin to login ...

[error] :.:.:.:.: Except return :.:.:.:.:
[error] Python Error: 
 Traceback (most recent call last):
  File "Actions/checkin.py", line 78, in <module>
    csrfToken = csrfToken.pop().attrib["content"]
IndexError: pop from empty list

:.:.:.:.: Finally :.:.:.:.:
[info] Notification sended at 2021-01-22 08:31:46 Friday
[info] Task Finished at 2021-01-22 08:31:46 Friday
============================

============================
[debug] Begin to login ...

[error] :.:.:.:.: Except return :.:.:.:.:
[error] Python Error: 
 Traceback (most recent call last):
  File "Actions/checkin.py", line 78, in <module>
    csrfToken = csrfToken.pop().attrib["content"]
IndexError: pop from empty list

:.:.:.:.: Finally :.:.:.:.:
[info] Notification sended at 2021-01-22 10:35:12 Friday
[info] Task Finished at 2021-01-22 10:35:12 Friday
============================

============================
[debug] Begin to login ...

[error] :.:.:.:.: Except return :.:.:.:.:
[error] Python Error: 
 Traceback (most recent call last):
  File "Actions/checkin.py", line 78, in <module>
    csrfToken = csrfToken.pop().attrib["content"]
IndexError: pop from empty list

:.:.:.:.: Finally :.:.:.:.:
[info] Notification sended at 2021-01-23 07:27:55 Saturday
[info] Task Finished at 2021-01-23 07:27:55 Saturday
============================

============================
[debug] Begin to login ...

[error] :.:.:.:.: Except return :.:.:.:.:
[error] Python Error: 
 Traceback (most recent call last):
  File "Actions/checkin.py", line 78, in <module>
    csrfToken = csrfToken.pop().attrib["content"]
IndexError: pop from empty list

:.:.:.:.: Finally :.:.:.:.:
[info] Notification sended at 2021-01-23 08:33:29 Saturday
[info] Task Finished at 2021-01-23 08:33:29 Saturday
============================

============================
[debug] Begin to login ...

[error] :.:.:.:.: Except return :.:.:.:.:
[error] Python Error: 
 Traceback (most recent call last):
  File "Actions/checkin.py", line 78, in <module>
    csrfToken = csrfToken.pop().attrib["content"]
IndexError: pop from empty list

:.:.:.:.: Finally :.:.:.:.:
[info] Notification sended at 2021-01-23 10:34:58 Saturday
[info] Task Finished at 2021-01-23 10:34:58 Saturday
============================

============================
[debug] Begin to login ...

[error] :.:.:.:.: Except return :.:.:.:.:
[error] Python Error: 
 Traceback (most recent call last):
  File "Actions/checkin.py", line 78, in <module>
    csrfToken = csrfToken.pop().attrib["content"]
IndexError: pop from empty list

:.:.:.:.: Finally :.:.:.:.:
[info] Notification sended at 2021-01-24 07:24:32 Sunday
[info] Task Finished at 2021-01-24 07:24:32 Sunday
============================

============================
[debug] Begin to login ...

[error] :.:.:.:.: Except return :.:.:.:.:
[error] Python Error: 
 Traceback (most recent call last):
  File "Actions/checkin.py", line 78, in <module>
    csrfToken = csrfToken.pop().attrib["content"]
IndexError: pop from empty list

:.:.:.:.: Finally :.:.:.:.:
[info] Notification sended at 2021-01-24 08:30:16 Sunday
[info] Task Finished at 2021-01-24 08:30:16 Sunday
============================

============================
[debug] Begin to login ...

[error] :.:.:.:.: Except return :.:.:.:.:
[error] Python Error: 
 Traceback (most recent call last):
  File "Actions/checkin.py", line 78, in <module>
    csrfToken = csrfToken.pop().attrib["content"]
IndexError: pop from empty list

:.:.:.:.: Finally :.:.:.:.:
[info] Notification sended at 2021-01-24 10:36:47 Sunday
[info] Task Finished at 2021-01-24 10:36:47 Sunday
============================

============================
[debug] Begin to login ...

[error] :.:.:.:.: Except return :.:.:.:.:
[error] Python Error: 
 Traceback (most recent call last):
  File "Actions/checkin.py", line 78, in <module>
    csrfToken = csrfToken.pop().attrib["content"]
IndexError: pop from empty list

:.:.:.:.: Finally :.:.:.:.:
[info] Notification sended at 2021-01-25 07:25:48 Monday
[info] Task Finished at 2021-01-25 07:25:48 Monday
============================

============================
[debug] Begin to login ...

[error] :.:.:.:.: Except return :.:.:.:.:
[error] Python Error: 
 Traceback (most recent call last):
  File "Actions/checkin.py", line 78, in <module>
    csrfToken = csrfToken.pop().attrib["content"]
IndexError: pop from empty list

:.:.:.:.: Finally :.:.:.:.:
[info] Notification sended at 2021-01-25 08:30:51 Monday
[info] Task Finished at 2021-01-25 08:30:51 Monday
============================

============================
[debug] Begin to login ...

[error] :.:.:.:.: Except return :.:.:.:.:
[error] Python Error: 
 Traceback (most recent call last):
  File "Actions/checkin.py", line 78, in <module>
    csrfToken = csrfToken.pop().attrib["content"]
IndexError: pop from empty list

:.:.:.:.: Finally :.:.:.:.:
[info] Notification sended at 2021-01-25 10:35:46 Monday
[info] Task Finished at 2021-01-25 10:35:46 Monday
============================

============================
[debug] Begin to login ...

[error] :.:.:.:.: Except return :.:.:.:.:
[error] Python Error: 
 Traceback (most recent call last):
  File "Actions/checkin.py", line 78, in <module>
    csrfToken = csrfToken.pop().attrib["content"]
IndexError: pop from empty list

:.:.:.:.: Finally :.:.:.:.:
[info] Notification sended at 2021-01-26 07:08:43 Tuesday
[info] Task Finished at 2021-01-26 07:08:43 Tuesday
============================

============================
[debug] Begin to login ...

[error] :.:.:.:.: Except return :.:.:.:.:
[error] Python Error: 
 Traceback (most recent call last):
  File "Actions/checkin.py", line 78, in <module>
    csrfToken = csrfToken.pop().attrib["content"]
IndexError: pop from empty list

:.:.:.:.: Finally :.:.:.:.:
[info] Notification sended at 2021-01-26 08:06:57 Tuesday
[info] Task Finished at 2021-01-26 08:06:57 Tuesday
============================

============================
[debug] Begin to login ...

[error] :.:.:.:.: Except return :.:.:.:.:
[error] Python Error: 
 Traceback (most recent call last):
  File "Actions/checkin.py", line 78, in <module>
    csrfToken = csrfToken.pop().attrib["content"]
IndexError: pop from empty list

:.:.:.:.: Finally :.:.:.:.:
[info] Notification sended at 2021-01-26 09:43:40 Tuesday
[info] Task Finished at 2021-01-26 09:43:40 Tuesday
============================

============================
[debug] Begin to login ...

[error] :.:.:.:.: Except return :.:.:.:.:
[error] Python Error: 
 Traceback (most recent call last):
  File "Actions/checkin.py", line 78, in <module>
    csrfToken = csrfToken.pop().attrib["content"]
IndexError: pop from empty list

:.:.:.:.: Finally :.:.:.:.:
[info] Notification sended at 2021-01-27 07:07:04 Wednesday
[info] Task Finished at 2021-01-27 07:07:04 Wednesday
============================

============================
[debug] Begin to login ...

[error] :.:.:.:.: Except return :.:.:.:.:
[error] Python Error: 
 Traceback (most recent call last):
  File "Actions/checkin.py", line 78, in <module>
    csrfToken = csrfToken.pop().attrib["content"]
IndexError: pop from empty list

:.:.:.:.: Finally :.:.:.:.:
[info] Notification sended at 2021-01-27 08:08:50 Wednesday
[info] Task Finished at 2021-01-27 08:08:50 Wednesday
============================

============================
[debug] Begin to login ...

[error] :.:.:.:.: Except return :.:.:.:.:
[error] Python Error: 
 Traceback (most recent call last):
  File "Actions/checkin.py", line 78, in <module>
    csrfToken = csrfToken.pop().attrib["content"]
IndexError: pop from empty list

:.:.:.:.: Finally :.:.:.:.:
[info] Notification sended at 2021-01-27 09:42:11 Wednesday
[info] Task Finished at 2021-01-27 09:42:11 Wednesday
============================

============================
[debug] Begin to login ...

[error] :.:.:.:.: Except return :.:.:.:.:
[error] Python Error: 
 Traceback (most recent call last):
  File "Actions/checkin.py", line 78, in <module>
    csrfToken = csrfToken.pop().attrib["content"]
IndexError: pop from empty list

:.:.:.:.: Finally :.:.:.:.:
[info] Notification sended at 2021-01-28 07:04:06 Thursday
[info] Task Finished at 2021-01-28 07:04:06 Thursday
============================

============================
[debug] Begin to login ...

[error] :.:.:.:.: Except return :.:.:.:.:
[error] Python Error: 
 Traceback (most recent call last):
  File "Actions/checkin.py", line 78, in <module>
    csrfToken = csrfToken.pop().attrib["content"]
IndexError: pop from empty list

:.:.:.:.: Finally :.:.:.:.:
[info] Notification sended at 2021-01-28 08:07:14 Thursday
[info] Task Finished at 2021-01-28 08:07:14 Thursday
============================

============================
[debug] Begin to login ...

[error] :.:.:.:.: Except return :.:.:.:.:
[error] Python Error: 
 Traceback (most recent call last):
  File "Actions/checkin.py", line 78, in <module>
    csrfToken = csrfToken.pop().attrib["content"]
IndexError: pop from empty list

:.:.:.:.: Finally :.:.:.:.:
[info] Notification sended at 2021-01-28 09:44:34 Thursday
[info] Task Finished at 2021-01-28 09:44:34 Thursday
============================

============================
[debug] Begin to login ...

[error] :.:.:.:.: Except return :.:.:.:.:
[error] Python Error: 
 Traceback (most recent call last):
  File "Actions/checkin.py", line 78, in <module>
    csrfToken = csrfToken.pop().attrib["content"]
IndexError: pop from empty list

:.:.:.:.: Finally :.:.:.:.:
[info] Notification sended at 2021-01-29 07:05:29 Friday
[info] Task Finished at 2021-01-29 07:05:29 Friday
============================

============================
[debug] Begin to login ...

[error] :.:.:.:.: Except return :.:.:.:.:
[error] Python Error: 
 Traceback (most recent call last):
  File "Actions/checkin.py", line 78, in <module>
    csrfToken = csrfToken.pop().attrib["content"]
IndexError: pop from empty list

:.:.:.:.: Finally :.:.:.:.:
[info] Notification sended at 2021-01-29 08:06:58 Friday
[info] Task Finished at 2021-01-29 08:06:58 Friday
============================

============================
[debug] Begin to login ...

[error] :.:.:.:.: Except return :.:.:.:.:
[error] Python Error: 
 Traceback (most recent call last):
  File "Actions/checkin.py", line 78, in <module>
    csrfToken = csrfToken.pop().attrib["content"]
IndexError: pop from empty list

:.:.:.:.: Finally :.:.:.:.:
[info] Notification sended at 2021-01-29 09:42:43 Friday
[info] Task Finished at 2021-01-29 09:42:43 Friday
============================

============================
[debug] Begin to login ...

[error] :.:.:.:.: Except return :.:.:.:.:
[error] Python Error: 
 Traceback (most recent call last):
  File "Actions/checkin.py", line 78, in <module>
    csrfToken = csrfToken.pop().attrib["content"]
IndexError: pop from empty list

:.:.:.:.: Finally :.:.:.:.:
[info] Notification sended at 2021-01-30 07:03:53 Saturday
[info] Task Finished at 2021-01-30 07:03:53 Saturday
============================

============================
[debug] Begin to login ...

[error] :.:.:.:.: Except return :.:.:.:.:
[error] Python Error: 
 Traceback (most recent call last):
  File "Actions/checkin.py", line 78, in <module>
    csrfToken = csrfToken.pop().attrib["content"]
IndexError: pop from empty list

:.:.:.:.: Finally :.:.:.:.:
[info] Notification sended at 2021-01-30 08:05:22 Saturday
[info] Task Finished at 2021-01-30 08:05:22 Saturday
============================

============================
[debug] Begin to login ...

[error] :.:.:.:.: Except return :.:.:.:.:
[error] Python Error: 
 Traceback (most recent call last):
  File "Actions/checkin.py", line 78, in <module>
    csrfToken = csrfToken.pop().attrib["content"]
IndexError: pop from empty list

:.:.:.:.: Finally :.:.:.:.:
============================
[debug] Begin to login ...

[error] :.:.:.:.: Except return :.:.:.:.:
[error] Python Error: 
 Traceback (most recent call last):
  File "Actions/checkin.py", line 78, in <module>
    csrfToken = csrfToken.pop().attrib["content"]
IndexError: pop from empty list

:.:.:.:.: Finally :.:.:.:.:
[info] Notification sended at 2021-01-31 07:03:39 Sunday
[info] Task Finished at 2021-01-31 07:03:39 Sunday
============================

============================
[debug] Begin to login ...

[error] :.:.:.:.: Except return :.:.:.:.:
[error] Python Error: 
 Traceback (most recent call last):
  File "Actions/checkin.py", line 78, in <module>
    csrfToken = csrfToken.pop().attrib["content"]
IndexError: pop from empty list

:.:.:.:.: Finally :.:.:.:.:
[info] Notification sended at 2021-01-31 08:05:30 Sunday
[info] Task Finished at 2021-01-31 08:05:30 Sunday
============================

============================
[debug] Begin to login ...

[error] :.:.:.:.: Except return :.:.:.:.:
[error] Python Error: 
 Traceback (most recent call last):
  File "Actions/checkin.py", line 78, in <module>
    csrfToken = csrfToken.pop().attrib["content"]
IndexError: pop from empty list

:.:.:.:.: Finally :.:.:.:.:
[info] Notification sended at 2021-01-31 09:46:29 Sunday
[info] Task Finished at 2021-01-31 09:46:29 Sunday
============================

============================
[debug] Begin to login ...

[error] :.:.:.:.: Except return :.:.:.:.:
[error] Python Error: 
 Traceback (most recent call last):
  File "Actions/checkin.py", line 78, in <module>
    csrfToken = csrfToken.pop().attrib["content"]
IndexError: pop from empty list

:.:.:.:.: Finally :.:.:.:.:
[info] Notification sended at 2021-02-01 07:03:54 Monday
[info] Task Finished at 2021-02-01 07:03:54 Monday
============================

============================
[debug] Begin to login ...

[error] :.:.:.:.: Except return :.:.:.:.:
[error] Python Error: 
 Traceback (most recent call last):
  File "Actions/checkin.py", line 78, in <module>
    csrfToken = csrfToken.pop().attrib["content"]
IndexError: pop from empty list

:.:.:.:.: Finally :.:.:.:.:
[info] Notification sended at 2021-02-01 08:05:54 Monday
[info] Task Finished at 2021-02-01 08:05:54 Monday
============================

============================
[debug] Begin to login ...

[error] :.:.:.:.: Except return :.:.:.:.:
[error] Python Error: 
 Traceback (most recent call last):
  File "Actions/checkin.py", line 78, in <module>
    csrfToken = csrfToken.pop().attrib["content"]
IndexError: pop from empty list

:.:.:.:.: Finally :.:.:.:.:
[info] Notification sended at 2021-02-01 09:47:06 Monday
[info] Task Finished at 2021-02-01 09:47:06 Monday
============================

============================
[debug] Begin to login ...

[error] :.:.:.:.: Except return :.:.:.:.:
[error] Python Error: 
 Traceback (most recent call last):
  File "Actions/checkin.py", line 78, in <module>
    csrfToken = csrfToken.pop().attrib["content"]
IndexError: pop from empty list

:.:.:.:.: Finally :.:.:.:.:
[info] Notification sended at 2021-02-02 07:05:00 Tuesday
[info] Task Finished at 2021-02-02 07:05:00 Tuesday
============================

============================
[debug] Begin to login ...

[error] :.:.:.:.: Except return :.:.:.:.:
[error] Python Error: 
 Traceback (most recent call last):
  File "Actions/checkin.py", line 78, in <module>
    csrfToken = csrfToken.pop().attrib["content"]
IndexError: pop from empty list

:.:.:.:.: Finally :.:.:.:.:
[info] Notification sended at 2021-02-02 08:06:52 Tuesday
[info] Task Finished at 2021-02-02 08:06:52 Tuesday
============================

============================
[debug] Begin to login ...

[error] :.:.:.:.: Except return :.:.:.:.:
[error] Python Error: 
 Traceback (most recent call last):
  File "Actions/checkin.py", line 78, in <module>
    csrfToken = csrfToken.pop().attrib["content"]
IndexError: pop from empty list

:.:.:.:.: Finally :.:.:.:.:
[info] Notification sended at 2021-02-02 09:47:00 Tuesday
[info] Task Finished at 2021-02-02 09:47:00 Tuesday
============================

============================
[debug] Begin to login ...

[error] :.:.:.:.: Except return :.:.:.:.:
[error] Python Error: 
 Traceback (most recent call last):
  File "Actions/checkin.py", line 78, in <module>
    csrfToken = csrfToken.pop().attrib["content"]
IndexError: pop from empty list

:.:.:.:.: Finally :.:.:.:.:
[info] Notification sended at 2021-02-03 07:05:55 Wednesday
[info] Task Finished at 2021-02-03 07:05:55 Wednesday
============================

============================
[debug] Begin to login ...

[error] :.:.:.:.: Except return :.:.:.:.:
[error] Python Error: 
 Traceback (most recent call last):
  File "Actions/checkin.py", line 78, in <module>
    csrfToken = csrfToken.pop().attrib["content"]
IndexError: pop from empty list

:.:.:.:.: Finally :.:.:.:.:
[info] Notification sended at 2021-02-03 08:02:56 Wednesday
[info] Task Finished at 2021-02-03 08:02:56 Wednesday
============================

============================
[debug] Begin to login ...

[error] :.:.:.:.: Except return :.:.:.:.:
[error] Python Error: 
 Traceback (most recent call last):
  File "Actions/checkin.py", line 78, in <module>
    csrfToken = csrfToken.pop().attrib["content"]
IndexError: pop from empty list

:.:.:.:.: Finally :.:.:.:.:
[info] Notification sended at 2021-02-03 09:33:48 Wednesday
[info] Task Finished at 2021-02-03 09:33:48 Wednesday
============================

============================
[debug] Begin to login ...

[error] :.:.:.:.: Except return :.:.:.:.:
[error] Python Error: 
 Traceback (most recent call last):
  File "Actions/checkin.py", line 78, in <module>
    csrfToken = csrfToken.pop().attrib["content"]
IndexError: pop from empty list

:.:.:.:.: Finally :.:.:.:.:
[info] Notification sended at 2021-02-04 07:01:40 Thursday
[info] Task Finished at 2021-02-04 07:01:40 Thursday
============================

============================
[debug] Begin to login ...

[error] :.:.:.:.: Except return :.:.:.:.:
[error] Python Error: 
 Traceback (most recent call last):
  File "Actions/checkin.py", line 78, in <module>
    csrfToken = csrfToken.pop().attrib["content"]
IndexError: pop from empty list

:.:.:.:.: Finally :.:.:.:.:
[info] Notification sended at 2021-02-04 08:03:11 Thursday
[info] Task Finished at 2021-02-04 08:03:11 Thursday
============================

============================
[debug] Begin to login ...

[error] :.:.:.:.: Except return :.:.:.:.:
[error] Python Error: 
 Traceback (most recent call last):
  File "Actions/checkin.py", line 78, in <module>
    csrfToken = csrfToken.pop().attrib["content"]
IndexError: pop from empty list

:.:.:.:.: Finally :.:.:.:.:
[info] Notification sended at 2021-02-04 09:25:51 Thursday
[info] Task Finished at 2021-02-04 09:25:51 Thursday
============================

============================
[debug] Begin to login ...

[error] :.:.:.:.: Except return :.:.:.:.:
[error] Python Error: 
 Traceback (most recent call last):
  File "Actions/checkin.py", line 78, in <module>
    csrfToken = csrfToken.pop().attrib["content"]
IndexError: pop from empty list

:.:.:.:.: Finally :.:.:.:.:
[info] Notification sended at 2021-02-05 07:02:40 Friday
[info] Task Finished at 2021-02-05 07:02:40 Friday
============================

============================
[debug] Begin to login ...

[error] :.:.:.:.: Except return :.:.:.:.:
[error] Python Error: 
 Traceback (most recent call last):
  File "Actions/checkin.py", line 78, in <module>
    csrfToken = csrfToken.pop().attrib["content"]
IndexError: pop from empty list

:.:.:.:.: Finally :.:.:.:.:
============================
[debug] Begin to login ...

[error] :.:.:.:.: Except return :.:.:.:.:
[error] Python Error: 
 Traceback (most recent call last):
  File "Actions/checkin.py", line 78, in <module>
    csrfToken = csrfToken.pop().attrib["content"]
IndexError: pop from empty list

:.:.:.:.: Finally :.:.:.:.:
[info] Notification sended at 2021-02-05 09:26:05 Friday
[info] Task Finished at 2021-02-05 09:26:05 Friday
============================

============================
[debug] Begin to login ...

[error] :.:.:.:.: Except return :.:.:.:.:
[error] Python Error: 
 Traceback (most recent call last):
  File "Actions/checkin.py", line 78, in <module>
    csrfToken = csrfToken.pop().attrib["content"]
IndexError: pop from empty list

:.:.:.:.: Finally :.:.:.:.:
[info] Notification sended at 2021-02-06 07:01:58 Saturday
[info] Task Finished at 2021-02-06 07:01:58 Saturday
============================

============================
[debug] Begin to login ...

[error] :.:.:.:.: Except return :.:.:.:.:
[error] Python Error: 
 Traceback (most recent call last):
  File "Actions/checkin.py", line 78, in <module>
    csrfToken = csrfToken.pop().attrib["content"]
IndexError: pop from empty list

:.:.:.:.: Finally :.:.:.:.:
[info] Notification sended at 2021-02-06 08:07:27 Saturday
[info] Task Finished at 2021-02-06 08:07:27 Saturday
============================

============================
[debug] Begin to login ...

[error] :.:.:.:.: Except return :.:.:.:.:
[error] Python Error: 
 Traceback (most recent call last):
  File "Actions/checkin.py", line 78, in <module>
    csrfToken = csrfToken.pop().attrib["content"]
IndexError: pop from empty list

:.:.:.:.: Finally :.:.:.:.:
[info] Notification sended at 2021-02-06 09:25:01 Saturday
[info] Task Finished at 2021-02-06 09:25:01 Saturday
============================

============================
[debug] Begin to login ...

[error] :.:.:.:.: Except return :.:.:.:.:
[error] Python Error: 
 Traceback (most recent call last):
  File "Actions/checkin.py", line 78, in <module>
    csrfToken = csrfToken.pop().attrib["content"]
IndexError: pop from empty list

:.:.:.:.: Finally :.:.:.:.:
[info] Notification sended at 2021-02-07 07:01:36 Sunday
[info] Task Finished at 2021-02-07 07:01:36 Sunday
============================

============================
[debug] Begin to login ...

[error] :.:.:.:.: Except return :.:.:.:.:
[error] Python Error: 
 Traceback (most recent call last):
  File "Actions/checkin.py", line 78, in <module>
    csrfToken = csrfToken.pop().attrib["content"]
IndexError: pop from empty list

:.:.:.:.: Finally :.:.:.:.:
[info] Notification sended at 2021-02-07 08:03:10 Sunday
[info] Task Finished at 2021-02-07 08:03:10 Sunday
============================

============================
[debug] Begin to login ...

[error] :.:.:.:.: Except return :.:.:.:.:
[error] Python Error: 
 Traceback (most recent call last):
  File "Actions/checkin.py", line 78, in <module>
    csrfToken = csrfToken.pop().attrib["content"]
IndexError: pop from empty list

:.:.:.:.: Finally :.:.:.:.:
[info] Notification sended at 2021-02-07 09:37:16 Sunday
[info] Task Finished at 2021-02-07 09:37:16 Sunday
============================

============================
[debug] Begin to login ...

[error] :.:.:.:.: Except return :.:.:.:.:
[error] Python Error: 
 Traceback (most recent call last):
  File "Actions/checkin.py", line 78, in <module>
    csrfToken = csrfToken.pop().attrib["content"]
IndexError: pop from empty list

:.:.:.:.: Finally :.:.:.:.:
[info] Notification sended at 2021-02-08 07:01:42 Monday
[info] Task Finished at 2021-02-08 07:01:42 Monday
============================

============================
[debug] Begin to login ...

[error] :.:.:.:.: Except return :.:.:.:.:
[error] Python Error: 
 Traceback (most recent call last):
  File "Actions/checkin.py", line 78, in <module>
    csrfToken = csrfToken.pop().attrib["content"]
IndexError: pop from empty list

:.:.:.:.: Finally :.:.:.:.:
[info] Notification sended at 2021-02-08 08:03:12 Monday
[info] Task Finished at 2021-02-08 08:03:12 Monday
============================

============================
[debug] Begin to login ...

[error] :.:.:.:.: Except return :.:.:.:.:
[error] Python Error: 
 Traceback (most recent call last):
  File "Actions/checkin.py", line 78, in <module>
    csrfToken = csrfToken.pop().attrib["content"]
IndexError: pop from empty list

:.:.:.:.: Finally :.:.:.:.:
[info] Notification sended at 2021-02-08 09:26:19 Monday
[info] Task Finished at 2021-02-08 09:26:19 Monday
============================

============================
[debug] Begin to login ...

[error] :.:.:.:.: Except return :.:.:.:.:
[error] Python Error: 
 Traceback (most recent call last):
  File "Actions/checkin.py", line 78, in <module>
    csrfToken = csrfToken.pop().attrib["content"]
IndexError: pop from empty list

:.:.:.:.: Finally :.:.:.:.:
[info] Notification sended at 2021-02-09 07:01:55 Tuesday
[info] Task Finished at 2021-02-09 07:01:55 Tuesday
============================

============================
[debug] Begin to login ...

[error] :.:.:.:.: Except return :.:.:.:.:
[error] Python Error: 
 Traceback (most recent call last):
  File "Actions/checkin.py", line 78, in <module>
    csrfToken = csrfToken.pop().attrib["content"]
IndexError: pop from empty list

:.:.:.:.: Finally :.:.:.:.:
[info] Notification sended at 2021-02-09 08:03:09 Tuesday
[info] Task Finished at 2021-02-09 08:03:09 Tuesday
============================

============================
[debug] Begin to login ...

[error] :.:.:.:.: Except return :.:.:.:.:
[error] Python Error: 
 Traceback (most recent call last):
  File "Actions/checkin.py", line 78, in <module>
    csrfToken = csrfToken.pop().attrib["content"]
IndexError: pop from empty list

:.:.:.:.: Finally :.:.:.:.:
[info] Notification sended at 2021-02-09 09:25:54 Tuesday
[info] Task Finished at 2021-02-09 09:25:54 Tuesday
============================

============================
[debug] Begin to login ...

[error] :.:.:.:.: Except return :.:.:.:.:
[error] Python Error: 
 Traceback (most recent call last):
  File "Actions/checkin.py", line 78, in <module>
    csrfToken = csrfToken.pop().attrib["content"]
IndexError: pop from empty list

:.:.:.:.: Finally :.:.:.:.:
[info] Notification sended at 2021-02-10 07:01:37 Wednesday
[info] Task Finished at 2021-02-10 07:01:37 Wednesday
============================

============================
[debug] Begin to login ...

[error] :.:.:.:.: Except return :.:.:.:.:
[error] Python Error: 
 Traceback (most recent call last):
  File "Actions/checkin.py", line 78, in <module>
    csrfToken = csrfToken.pop().attrib["content"]
IndexError: pop from empty list

:.:.:.:.: Finally :.:.:.:.:
[info] Notification sended at 2021-02-10 08:03:19 Wednesday
[info] Task Finished at 2021-02-10 08:03:19 Wednesday
============================

============================
[debug] Begin to login ...

[error] :.:.:.:.: Except return :.:.:.:.:
[error] Python Error: 
 Traceback (most recent call last):
  File "Actions/checkin.py", line 78, in <module>
    csrfToken = csrfToken.pop().attrib["content"]
IndexError: pop from empty list

:.:.:.:.: Finally :.:.:.:.:
[info] Notification sended at 2021-02-10 09:25:20 Wednesday
[info] Task Finished at 2021-02-10 09:25:20 Wednesday
============================

============================
[debug] Begin to login ...

[error] :.:.:.:.: Except return :.:.:.:.:
[error] Python Error: 
 Traceback (most recent call last):
  File "Actions/checkin.py", line 78, in <module>
    csrfToken = csrfToken.pop().attrib["content"]
IndexError: pop from empty list

:.:.:.:.: Finally :.:.:.:.:
[info] Notification sended at 2021-02-11 07:01:50 Thursday
[info] Task Finished at 2021-02-11 07:01:50 Thursday
============================

============================
[debug] Begin to login ...

[error] :.:.:.:.: Except return :.:.:.:.:
[error] Python Error: 
 Traceback (most recent call last):
  File "Actions/checkin.py", line 78, in <module>
    csrfToken = csrfToken.pop().attrib["content"]
IndexError: pop from empty list

:.:.:.:.: Finally :.:.:.:.:
[info] Notification sended at 2021-02-11 08:03:20 Thursday
[info] Task Finished at 2021-02-11 08:03:20 Thursday
============================

============================
[debug] Begin to login ...

[error] :.:.:.:.: Except return :.:.:.:.:
[error] Python Error: 
 Traceback (most recent call last):
  File "Actions/checkin.py", line 78, in <module>
    csrfToken = csrfToken.pop().attrib["content"]
IndexError: pop from empty list

:.:.:.:.: Finally :.:.:.:.:
[info] Notification sended at 2021-02-11 09:29:17 Thursday
[info] Task Finished at 2021-02-11 09:29:17 Thursday
============================

============================
[debug] Begin to login ...

[error] :.:.:.:.: Except return :.:.:.:.:
[error] Python Error: 
 Traceback (most recent call last):
  File "Actions/checkin.py", line 78, in <module>
    csrfToken = csrfToken.pop().attrib["content"]
IndexError: pop from empty list

:.:.:.:.: Finally :.:.:.:.:
[info] Notification sended at 2021-02-12 07:01:34 Friday
[info] Task Finished at 2021-02-12 07:01:34 Friday
============================

============================
[debug] Begin to login ...

[error] :.:.:.:.: Except return :.:.:.:.:
[error] Python Error: 
 Traceback (most recent call last):
  File "Actions/checkin.py", line 78, in <module>
    csrfToken = csrfToken.pop().attrib["content"]
IndexError: pop from empty list

:.:.:.:.: Finally :.:.:.:.:
[info] Notification sended at 2021-02-12 08:07:35 Friday
[info] Task Finished at 2021-02-12 08:07:35 Friday
============================

============================
[debug] Begin to login ...

[error] :.:.:.:.: Except return :.:.:.:.:
[error] Python Error: 
 Traceback (most recent call last):
  File "Actions/checkin.py", line 78, in <module>
    csrfToken = csrfToken.pop().attrib["content"]
IndexError: pop from empty list

:.:.:.:.: Finally :.:.:.:.:
[info] Notification sended at 2021-02-12 09:26:20 Friday
[info] Task Finished at 2021-02-12 09:26:20 Friday
============================

============================
[debug] Begin to login ...

[error] :.:.:.:.: Except return :.:.:.:.:
[error] Python Error: 
 Traceback (most recent call last):
  File "Actions/checkin.py", line 78, in <module>
    csrfToken = csrfToken.pop().attrib["content"]
IndexError: pop from empty list

:.:.:.:.: Finally :.:.:.:.:
[info] Notification sended at 2021-02-13 07:01:36 Saturday
[info] Task Finished at 2021-02-13 07:01:36 Saturday
============================

============================
[debug] Begin to login ...

[error] :.:.:.:.: Except return :.:.:.:.:
[error] Python Error: 
 Traceback (most recent call last):
  File "Actions/checkin.py", line 78, in <module>
    csrfToken = csrfToken.pop().attrib["content"]
IndexError: pop from empty list

:.:.:.:.: Finally :.:.:.:.:
[info] Notification sended at 2021-02-13 08:03:07 Saturday
[info] Task Finished at 2021-02-13 08:03:07 Saturday
============================

============================
[debug] Begin to login ...

[error] :.:.:.:.: Except return :.:.:.:.:
[error] Python Error: 
 Traceback (most recent call last):
  File "Actions/checkin.py", line 78, in <module>
    csrfToken = csrfToken.pop().attrib["content"]
IndexError: pop from empty list

:.:.:.:.: Finally :.:.:.:.:
[info] Notification sended at 2021-02-13 09:26:21 Saturday
[info] Task Finished at 2021-02-13 09:26:21 Saturday
============================

============================
[debug] Begin to login ...

[error] :.:.:.:.: Except return :.:.:.:.:
[error] Python Error: 
 Traceback (most recent call last):
  File "Actions/checkin.py", line 78, in <module>
    csrfToken = csrfToken.pop().attrib["content"]
IndexError: pop from empty list

:.:.:.:.: Finally :.:.:.:.:
[info] Notification sended at 2021-02-14 07:02:06 Sunday
[info] Task Finished at 2021-02-14 07:02:06 Sunday
============================

============================
[debug] Begin to login ...

[error] :.:.:.:.: Except return :.:.:.:.:
[error] Python Error: 
 Traceback (most recent call last):
  File "Actions/checkin.py", line 78, in <module>
    csrfToken = csrfToken.pop().attrib["content"]
IndexError: pop from empty list

:.:.:.:.: Finally :.:.:.:.:
[info] Notification sended at 2021-02-14 08:03:34 Sunday
[info] Task Finished at 2021-02-14 08:03:34 Sunday
============================

============================
[debug] Begin to login ...

[error] :.:.:.:.: Except return :.:.:.:.:
[error] Python Error: 
 Traceback (most recent call last):
  File "Actions/checkin.py", line 78, in <module>
    csrfToken = csrfToken.pop().attrib["content"]
IndexError: pop from empty list

:.:.:.:.: Finally :.:.:.:.:
[info] Notification sended at 2021-02-14 09:28:15 Sunday
[info] Task Finished at 2021-02-14 09:28:15 Sunday
============================

============================
[debug] Begin to login ...

[error] :.:.:.:.: Except return :.:.:.:.:
[error] Python Error: 
 Traceback (most recent call last):
  File "Actions/checkin.py", line 78, in <module>
    csrfToken = csrfToken.pop().attrib["content"]
IndexError: pop from empty list

:.:.:.:.: Finally :.:.:.:.:
[info] Notification sended at 2021-02-15 07:01:36 Monday
[info] Task Finished at 2021-02-15 07:01:36 Monday
============================

============================
[debug] Begin to login ...

[error] :.:.:.:.: Except return :.:.:.:.:
[error] Python Error: 
 Traceback (most recent call last):
  File "Actions/checkin.py", line 78, in <module>
    csrfToken = csrfToken.pop().attrib["content"]
IndexError: pop from empty list

:.:.:.:.: Finally :.:.:.:.:
[info] Notification sended at 2021-02-15 08:03:54 Monday
[info] Task Finished at 2021-02-15 08:03:54 Monday
============================

============================
[debug] Begin to login ...

[error] :.:.:.:.: Except return :.:.:.:.:
[error] Python Error: 
 Traceback (most recent call last):
  File "Actions/checkin.py", line 78, in <module>
    csrfToken = csrfToken.pop().attrib["content"]
IndexError: pop from empty list

:.:.:.:.: Finally :.:.:.:.:
[info] Notification sended at 2021-02-15 09:27:18 Monday
[info] Task Finished at 2021-02-15 09:27:18 Monday
============================

============================
[debug] Begin to login ...

[error] :.:.:.:.: Except return :.:.:.:.:
[error] Python Error: 
 Traceback (most recent call last):
  File "Actions/checkin.py", line 78, in <module>
    csrfToken = csrfToken.pop().attrib["content"]
IndexError: pop from empty list

:.:.:.:.: Finally :.:.:.:.:
[info] Notification sended at 2021-02-16 07:01:32 Tuesday
[info] Task Finished at 2021-02-16 07:01:32 Tuesday
============================

============================
[debug] Begin to login ...

[error] :.:.:.:.: Except return :.:.:.:.:
[error] Python Error: 
 Traceback (most recent call last):
  File "Actions/checkin.py", line 78, in <module>
    csrfToken = csrfToken.pop().attrib["content"]
IndexError: pop from empty list

:.:.:.:.: Finally :.:.:.:.:
[info] Notification sended at 2021-02-16 08:03:06 Tuesday
[info] Task Finished at 2021-02-16 08:03:06 Tuesday
============================

============================
[debug] Begin to login ...

[error] :.:.:.:.: Except return :.:.:.:.:
[error] Python Error: 
 Traceback (most recent call last):
  File "Actions/checkin.py", line 78, in <module>
    csrfToken = csrfToken.pop().attrib["content"]
IndexError: pop from empty list

:.:.:.:.: Finally :.:.:.:.:
[info] Notification sended at 2021-02-16 09:27:35 Tuesday
[info] Task Finished at 2021-02-16 09:27:35 Tuesday
============================

============================
[debug] Begin to login ...

[error] :.:.:.:.: Except return :.:.:.:.:
[error] Python Error: 
 Traceback (most recent call last):
  File "Actions/checkin.py", line 78, in <module>
    csrfToken = csrfToken.pop().attrib["content"]
IndexError: pop from empty list

:.:.:.:.: Finally :.:.:.:.:
[info] Notification sended at 2021-02-17 07:01:54 Wednesday
[info] Task Finished at 2021-02-17 07:01:54 Wednesday
============================

============================
[debug] Begin to login ...

[error] :.:.:.:.: Except return :.:.:.:.:
[error] Python Error: 
 Traceback (most recent call last):
  File "Actions/checkin.py", line 78, in <module>
    csrfToken = csrfToken.pop().attrib["content"]
IndexError: pop from empty list

:.:.:.:.: Finally :.:.:.:.:
[info] Notification sended at 2021-02-17 08:03:16 Wednesday
[info] Task Finished at 2021-02-17 08:03:16 Wednesday
============================

============================
[debug] Begin to login ...

[error] :.:.:.:.: Except return :.:.:.:.:
[error] Python Error: 
 Traceback (most recent call last):
  File "Actions/checkin.py", line 78, in <module>
    csrfToken = csrfToken.pop().attrib["content"]
IndexError: pop from empty list

:.:.:.:.: Finally :.:.:.:.:
[info] Notification sended at 2021-02-17 09:26:38 Wednesday
[info] Task Finished at 2021-02-17 09:26:38 Wednesday
============================

============================
[debug] Begin to login ...

[error] :.:.:.:.: Except return :.:.:.:.:
[error] Python Error: 
 Traceback (most recent call last):
  File "Actions/checkin.py", line 78, in <module>
    csrfToken = csrfToken.pop().attrib["content"]
IndexError: pop from empty list

:.:.:.:.: Finally :.:.:.:.:
[info] Notification sended at 2021-02-18 07:01:45 Thursday
[info] Task Finished at 2021-02-18 07:01:45 Thursday
============================

============================
[debug] Begin to login ...

[error] :.:.:.:.: Except return :.:.:.:.:
[error] Python Error: 
 Traceback (most recent call last):
  File "Actions/checkin.py", line 78, in <module>
    csrfToken = csrfToken.pop().attrib["content"]
IndexError: pop from empty list

:.:.:.:.: Finally :.:.:.:.:
[info] Notification sended at 2021-02-18 08:03:29 Thursday
[info] Task Finished at 2021-02-18 08:03:29 Thursday
============================

============================
[debug] Begin to login ...

[error] :.:.:.:.: Except return :.:.:.:.:
[error] Python Error: 
 Traceback (most recent call last):
  File "Actions/checkin.py", line 78, in <module>
    csrfToken = csrfToken.pop().attrib["content"]
IndexError: pop from empty list

:.:.:.:.: Finally :.:.:.:.:
[info] Notification sended at 2021-02-18 09:27:11 Thursday
[info] Task Finished at 2021-02-18 09:27:11 Thursday
============================

============================
[debug] Begin to login ...

[error] :.:.:.:.: Except return :.:.:.:.:
[error] Python Error: 
 Traceback (most recent call last):
  File "Actions/checkin.py", line 78, in <module>
    csrfToken = csrfToken.pop().attrib["content"]
IndexError: pop from empty list

:.:.:.:.: Finally :.:.:.:.:
[info] Notification sended at 2021-02-19 07:01:35 Friday
[info] Task Finished at 2021-02-19 07:01:35 Friday
============================

============================
[debug] Begin to login ...

[error] :.:.:.:.: Except return :.:.:.:.:
[error] Python Error: 
 Traceback (most recent call last):
  File "Actions/checkin.py", line 78, in <module>
    csrfToken = csrfToken.pop().attrib["content"]
IndexError: pop from empty list

:.:.:.:.: Finally :.:.:.:.:
[info] Notification sended at 2021-02-19 08:03:16 Friday
[info] Task Finished at 2021-02-19 08:03:16 Friday
============================

============================
[debug] Begin to login ...

[error] :.:.:.:.: Except return :.:.:.:.:
[error] Python Error: 
 Traceback (most recent call last):
  File "Actions/checkin.py", line 78, in <module>
    csrfToken = csrfToken.pop().attrib["content"]
IndexError: pop from empty list

:.:.:.:.: Finally :.:.:.:.:
[info] Notification sended at 2021-02-19 09:27:23 Friday
[info] Task Finished at 2021-02-19 09:27:23 Friday
============================

============================
[debug] Begin to login ...

[error] :.:.:.:.: Except return :.:.:.:.:
[error] Python Error: 
 Traceback (most recent call last):
  File "Actions/checkin.py", line 78, in <module>
    csrfToken = csrfToken.pop().attrib["content"]
IndexError: pop from empty list

:.:.:.:.: Finally :.:.:.:.:
[info] Notification sended at 2021-02-20 07:01:32 Saturday
[info] Task Finished at 2021-02-20 07:01:32 Saturday
============================

============================
[debug] Begin to login ...

[error] :.:.:.:.: Except return :.:.:.:.:
[error] Python Error: 
 Traceback (most recent call last):
  File "Actions/checkin.py", line 78, in <module>
    csrfToken = csrfToken.pop().attrib["content"]
IndexError: pop from empty list

:.:.:.:.: Finally :.:.:.:.:
============================
[debug] Begin to login ...

[error] :.:.:.:.: Except return :.:.:.:.:
[error] Python Error: 
 Traceback (most recent call last):
  File "Actions/checkin.py", line 78, in <module>
    csrfToken = csrfToken.pop().attrib["content"]
IndexError: pop from empty list

:.:.:.:.: Finally :.:.:.:.:
[info] Notification sended at 2021-02-20 09:26:42 Saturday
[info] Task Finished at 2021-02-20 09:26:42 Saturday
============================

============================
[debug] Begin to login ...

[error] :.:.:.:.: Except return :.:.:.:.:
[error] Python Error: 
 Traceback (most recent call last):
  File "Actions/checkin.py", line 78, in <module>
    csrfToken = csrfToken.pop().attrib["content"]
IndexError: pop from empty list

:.:.:.:.: Finally :.:.:.:.:
[info] Notification sended at 2021-02-21 07:01:45 Sunday
[info] Task Finished at 2021-02-21 07:01:45 Sunday
============================

============================
[debug] Begin to login ...

[error] :.:.:.:.: Except return :.:.:.:.:
[error] Python Error: 
 Traceback (most recent call last):
  File "Actions/checkin.py", line 78, in <module>
    csrfToken = csrfToken.pop().attrib["content"]
IndexError: pop from empty list

:.:.:.:.: Finally :.:.:.:.:
[info] Notification sended at 2021-02-21 08:03:23 Sunday
[info] Task Finished at 2021-02-21 08:03:23 Sunday
============================

============================
[debug] Begin to login ...

[error] :.:.:.:.: Except return :.:.:.:.:
[error] Python Error: 
 Traceback (most recent call last):
  File "Actions/checkin.py", line 78, in <module>
    csrfToken = csrfToken.pop().attrib["content"]
IndexError: pop from empty list

:.:.:.:.: Finally :.:.:.:.:
[info] Notification sended at 2021-02-21 09:29:39 Sunday
[info] Task Finished at 2021-02-21 09:29:39 Sunday
============================

============================
[debug] Begin to login ...

[error] :.:.:.:.: Except return :.:.:.:.:
[error] Python Error: 
 Traceback (most recent call last):
  File "Actions/checkin.py", line 78, in <module>
    csrfToken = csrfToken.pop().attrib["content"]
IndexError: pop from empty list

:.:.:.:.: Finally :.:.:.:.:
[info] Notification sended at 2021-02-22 07:01:56 Monday
[info] Task Finished at 2021-02-22 07:01:56 Monday
============================

============================
[debug] Begin to login ...

[error] :.:.:.:.: Except return :.:.:.:.:
[error] Python Error: 
 Traceback (most recent call last):
  File "Actions/checkin.py", line 78, in <module>
    csrfToken = csrfToken.pop().attrib["content"]
IndexError: pop from empty list

:.:.:.:.: Finally :.:.:.:.:
[info] Notification sended at 2021-02-22 08:03:41 Monday
[info] Task Finished at 2021-02-22 08:03:41 Monday
============================

============================
[debug] Begin to login ...

[error] :.:.:.:.: Except return :.:.:.:.:
[error] Python Error: 
 Traceback (most recent call last):
  File "Actions/checkin.py", line 78, in <module>
    csrfToken = csrfToken.pop().attrib["content"]
IndexError: pop from empty list

:.:.:.:.: Finally :.:.:.:.:
[info] Notification sended at 2021-02-22 09:28:48 Monday
[info] Task Finished at 2021-02-22 09:28:48 Monday
============================

============================
[debug] Begin to login ...

[error] :.:.:.:.: Except return :.:.:.:.:
[error] Python Error: 
 Traceback (most recent call last):
  File "Actions/checkin.py", line 78, in <module>
    csrfToken = csrfToken.pop().attrib["content"]
IndexError: pop from empty list

:.:.:.:.: Finally :.:.:.:.:
[info] Notification sended at 2021-02-23 07:01:40 Tuesday
[info] Task Finished at 2021-02-23 07:01:40 Tuesday
============================

============================
[debug] Begin to login ...

[error] :.:.:.:.: Except return :.:.:.:.:
[error] Python Error: 
 Traceback (most recent call last):
  File "Actions/checkin.py", line 78, in <module>
    csrfToken = csrfToken.pop().attrib["content"]
IndexError: pop from empty list

:.:.:.:.: Finally :.:.:.:.:
[info] Notification sended at 2021-02-23 08:03:08 Tuesday
[info] Task Finished at 2021-02-23 08:03:08 Tuesday
============================

============================
[debug] Begin to login ...

[error] :.:.:.:.: Except return :.:.:.:.:
[error] Python Error: 
 Traceback (most recent call last):
  File "Actions/checkin.py", line 78, in <module>
    csrfToken = csrfToken.pop().attrib["content"]
IndexError: pop from empty list

:.:.:.:.: Finally :.:.:.:.:
[info] Notification sended at 2021-02-23 09:28:32 Tuesday
[info] Task Finished at 2021-02-23 09:28:32 Tuesday
============================

============================
[debug] Begin to login ...

[error] :.:.:.:.: Except return :.:.:.:.:
[error] Python Error: 
 Traceback (most recent call last):
  File "Actions/checkin.py", line 78, in <module>
    csrfToken = csrfToken.pop().attrib["content"]
IndexError: pop from empty list

:.:.:.:.: Finally :.:.:.:.:
[info] Notification sended at 2021-02-24 07:01:37 Wednesday
[info] Task Finished at 2021-02-24 07:01:37 Wednesday
============================

============================
[debug] Begin to login ...

[error] :.:.:.:.: Except return :.:.:.:.:
[error] Python Error: 
 Traceback (most recent call last):
  File "Actions/checkin.py", line 78, in <module>
    csrfToken = csrfToken.pop().attrib["content"]
IndexError: pop from empty list

:.:.:.:.: Finally :.:.:.:.:
[info] Notification sended at 2021-02-24 08:03:30 Wednesday
[info] Task Finished at 2021-02-24 08:03:30 Wednesday
============================

============================
[debug] Begin to login ...

[error] :.:.:.:.: Except return :.:.:.:.:
[error] Python Error: 
 Traceback (most recent call last):
  File "Actions/checkin.py", line 78, in <module>
    csrfToken = csrfToken.pop().attrib["content"]
IndexError: pop from empty list

:.:.:.:.: Finally :.:.:.:.:
[info] Notification sended at 2021-02-24 09:29:38 Wednesday
[info] Task Finished at 2021-02-24 09:29:38 Wednesday
============================

============================
[debug] Begin to login ...

[error] :.:.:.:.: Except return :.:.:.:.:
[error] Python Error: 
 Traceback (most recent call last):
  File "Actions/checkin.py", line 78, in <module>
    csrfToken = csrfToken.pop().attrib["content"]
IndexError: pop from empty list

:.:.:.:.: Finally :.:.:.:.:
[info] Notification sended at 2021-02-25 07:02:02 Thursday
[info] Task Finished at 2021-02-25 07:02:02 Thursday
============================

============================
[debug] Begin to login ...

[error] :.:.:.:.: Except return :.:.:.:.:
[error] Python Error: 
 Traceback (most recent call last):
  File "Actions/checkin.py", line 78, in <module>
    csrfToken = csrfToken.pop().attrib["content"]
IndexError: pop from empty list

:.:.:.:.: Finally :.:.:.:.:
[info] Notification sended at 2021-02-25 08:03:08 Thursday
[info] Task Finished at 2021-02-25 08:03:08 Thursday
============================

============================
[debug] Begin to login ...

[error] :.:.:.:.: Except return :.:.:.:.:
[error] Python Error: 
 Traceback (most recent call last):
  File "Actions/checkin.py", line 78, in <module>
    csrfToken = csrfToken.pop().attrib["content"]
IndexError: pop from empty list

:.:.:.:.: Finally :.:.:.:.:
[info] Notification sended at 2021-02-25 09:29:29 Thursday
[info] Task Finished at 2021-02-25 09:29:29 Thursday
============================

============================
[debug] Begin to login ...

[error] :.:.:.:.: Except return :.:.:.:.:
[error] Python Error: 
 Traceback (most recent call last):
  File "Actions/checkin.py", line 78, in <module>
    csrfToken = csrfToken.pop().attrib["content"]
IndexError: pop from empty list

:.:.:.:.: Finally :.:.:.:.:
[info] Notification sended at 2021-02-26 07:02:03 Friday
[info] Task Finished at 2021-02-26 07:02:03 Friday
============================

============================
[debug] Begin to login ...

[error] :.:.:.:.: Except return :.:.:.:.:
[error] Python Error: 
 Traceback (most recent call last):
  File "Actions/checkin.py", line 78, in <module>
    csrfToken = csrfToken.pop().attrib["content"]
IndexError: pop from empty list

:.:.:.:.: Finally :.:.:.:.:
[info] Notification sended at 2021-02-26 08:03:11 Friday
[info] Task Finished at 2021-02-26 08:03:11 Friday
============================

============================
[debug] Begin to login ...

[error] :.:.:.:.: Except return :.:.:.:.:
[error] Python Error: 
 Traceback (most recent call last):
  File "Actions/checkin.py", line 78, in <module>
    csrfToken = csrfToken.pop().attrib["content"]
IndexError: pop from empty list

:.:.:.:.: Finally :.:.:.:.:
[info] Notification sended at 2021-02-26 09:29:44 Friday
[info] Task Finished at 2021-02-26 09:29:44 Friday
============================

============================
[debug] Begin to login ...

[error] :.:.:.:.: Except return :.:.:.:.:
[error] Python Error: 
 Traceback (most recent call last):
  File "Actions/checkin.py", line 78, in <module>
    csrfToken = csrfToken.pop().attrib["content"]
IndexError: pop from empty list

:.:.:.:.: Finally :.:.:.:.:
[info] Notification sended at 2021-02-27 07:01:51 Saturday
[info] Task Finished at 2021-02-27 07:01:51 Saturday
============================

============================
[debug] Begin to login ...

[error] :.:.:.:.: Except return :.:.:.:.:
[error] Python Error: 
 Traceback (most recent call last):
  File "Actions/checkin.py", line 78, in <module>
    csrfToken = csrfToken.pop().attrib["content"]
IndexError: pop from empty list

:.:.:.:.: Finally :.:.:.:.:
[info] Notification sended at 2021-02-27 08:03:21 Saturday
[info] Task Finished at 2021-02-27 08:03:21 Saturday
============================

============================
[debug] Begin to login ...

[error] :.:.:.:.: Except return :.:.:.:.:
[error] Python Error: 
 Traceback (most recent call last):
  File "Actions/checkin.py", line 78, in <module>
    csrfToken = csrfToken.pop().attrib["content"]
IndexError: pop from empty list

:.:.:.:.: Finally :.:.:.:.:
[info] Notification sended at 2021-02-27 09:29:29 Saturday
[info] Task Finished at 2021-02-27 09:29:29 Saturday
============================

============================
[debug] Begin to login ...

[error] :.:.:.:.: Except return :.:.:.:.:
[error] Python Error: 
 Traceback (most recent call last):
  File "Actions/checkin.py", line 78, in <module>
    csrfToken = csrfToken.pop().attrib["content"]
IndexError: pop from empty list

:.:.:.:.: Finally :.:.:.:.:
[info] Notification sended at 2021-02-28 07:01:46 Sunday
[info] Task Finished at 2021-02-28 07:01:46 Sunday
============================

============================
[debug] Begin to login ...

[error] :.:.:.:.: Except return :.:.:.:.:
[error] Python Error: 
 Traceback (most recent call last):
  File "Actions/checkin.py", line 78, in <module>
    csrfToken = csrfToken.pop().attrib["content"]
IndexError: pop from empty list

:.:.:.:.: Finally :.:.:.:.:
[info] Notification sended at 2021-02-28 08:03:30 Sunday
[info] Task Finished at 2021-02-28 08:03:30 Sunday
============================

============================
[debug] Begin to login ...

[error] :.:.:.:.: Except return :.:.:.:.:
[error] Python Error: 
 Traceback (most recent call last):
  File "Actions/checkin.py", line 78, in <module>
    csrfToken = csrfToken.pop().attrib["content"]
IndexError: pop from empty list

:.:.:.:.: Finally :.:.:.:.:
[info] Notification sended at 2021-02-28 09:32:24 Sunday
[info] Task Finished at 2021-02-28 09:32:24 Sunday
============================

============================
[debug] Begin to login ...

[error] :.:.:.:.: Except return :.:.:.:.:
[error] Python Error: 
 Traceback (most recent call last):
  File "Actions/checkin.py", line 78, in <module>
    csrfToken = csrfToken.pop().attrib["content"]
IndexError: pop from empty list

:.:.:.:.: Finally :.:.:.:.:
============================
[debug] Begin to login ...

[error] :.:.:.:.: Except return :.:.:.:.:
[error] Python Error: 
 Traceback (most recent call last):
  File "Actions/checkin.py", line 78, in <module>
    csrfToken = csrfToken.pop().attrib["content"]
IndexError: pop from empty list

:.:.:.:.: Finally :.:.:.:.:
[info] Notification sended at 2021-03-01 08:03:28 Monday
[info] Task Finished at 2021-03-01 08:03:28 Monday
============================

============================
[debug] Begin to login ...

[error] :.:.:.:.: Except return :.:.:.:.:
[error] Python Error: 
 Traceback (most recent call last):
  File "Actions/checkin.py", line 78, in <module>
    csrfToken = csrfToken.pop().attrib["content"]
IndexError: pop from empty list

:.:.:.:.: Finally :.:.:.:.:
[info] Notification sended at 2021-03-01 09:33:24 Monday
[info] Task Finished at 2021-03-01 09:33:24 Monday
============================

============================
[debug] Begin to login ...

[error] :.:.:.:.: Except return :.:.:.:.:
[error] Python Error: 
 Traceback (most recent call last):
  File "Actions/checkin.py", line 78, in <module>
    csrfToken = csrfToken.pop().attrib["content"]
IndexError: pop from empty list

:.:.:.:.: Finally :.:.:.:.:
[info] Notification sended at 2021-03-02 07:01:42 Tuesday
[info] Task Finished at 2021-03-02 07:01:42 Tuesday
============================

============================
[debug] Begin to login ...

[error] :.:.:.:.: Except return :.:.:.:.:
[error] Python Error: 
 Traceback (most recent call last):
  File "Actions/checkin.py", line 78, in <module>
    csrfToken = csrfToken.pop().attrib["content"]
IndexError: pop from empty list

:.:.:.:.: Finally :.:.:.:.:
[info] Notification sended at 2021-03-02 08:02:54 Tuesday
[info] Task Finished at 2021-03-02 08:02:54 Tuesday
============================

============================
[debug] Begin to login ...

[error] :.:.:.:.: Except return :.:.:.:.:
[error] Python Error: 
 Traceback (most recent call last):
  File "Actions/checkin.py", line 78, in <module>
    csrfToken = csrfToken.pop().attrib["content"]
IndexError: pop from empty list

:.:.:.:.: Finally :.:.:.:.:
[info] Notification sended at 2021-03-02 09:17:30 Tuesday
[info] Task Finished at 2021-03-02 09:17:30 Tuesday
============================

============================
[debug] Begin to login ...

[error] :.:.:.:.: Except return :.:.:.:.:
[error] Python Error: 
 Traceback (most recent call last):
  File "Actions/checkin.py", line 78, in <module>
    csrfToken = csrfToken.pop().attrib["content"]
IndexError: pop from empty list

:.:.:.:.: Finally :.:.:.:.:
[info] Notification sended at 2021-03-03 07:01:34 Wednesday
[info] Task Finished at 2021-03-03 07:01:34 Wednesday
============================

============================
[debug] Begin to login ...

[error] :.:.:.:.: Except return :.:.:.:.:
[error] Python Error: 
 Traceback (most recent call last):
  File "Actions/checkin.py", line 78, in <module>
    csrfToken = csrfToken.pop().attrib["content"]
IndexError: pop from empty list

:.:.:.:.: Finally :.:.:.:.:
[info] Notification sended at 2021-03-03 08:03:21 Wednesday
[info] Task Finished at 2021-03-03 08:03:21 Wednesday
============================

============================
[debug] Begin to login ...

[error] :.:.:.:.: Except return :.:.:.:.:
[error] Python Error: 
 Traceback (most recent call last):
  File "Actions/checkin.py", line 78, in <module>
    csrfToken = csrfToken.pop().attrib["content"]
IndexError: pop from empty list

:.:.:.:.: Finally :.:.:.:.:
[info] Notification sended at 2021-03-03 09:31:01 Wednesday
[info] Task Finished at 2021-03-03 09:31:01 Wednesday
============================

============================
[debug] Begin to login ...

[error] :.:.:.:.: Except return :.:.:.:.:
[error] Python Error: 
 Traceback (most recent call last):
  File "Actions/checkin.py", line 78, in <module>
    csrfToken = csrfToken.pop().attrib["content"]
IndexError: pop from empty list

:.:.:.:.: Finally :.:.:.:.:
[info] Notification sended at 2021-03-04 07:01:36 Thursday
[info] Task Finished at 2021-03-04 07:01:36 Thursday
============================

============================
[debug] Begin to login ...

[error] :.:.:.:.: Except return :.:.:.:.:
[error] Python Error: 
 Traceback (most recent call last):
  File "Actions/checkin.py", line 78, in <module>
    csrfToken = csrfToken.pop().attrib["content"]
IndexError: pop from empty list

:.:.:.:.: Finally :.:.:.:.:
[info] Notification sended at 2021-03-04 08:03:07 Thursday
[info] Task Finished at 2021-03-04 08:03:07 Thursday
============================

============================
[debug] Begin to login ...

[error] :.:.:.:.: Except return :.:.:.:.:
[error] Python Error: 
 Traceback (most recent call last):
  File "Actions/checkin.py", line 78, in <module>
    csrfToken = csrfToken.pop().attrib["content"]
IndexError: pop from empty list

:.:.:.:.: Finally :.:.:.:.:
[info] Notification sended at 2021-03-04 09:31:21 Thursday
[info] Task Finished at 2021-03-04 09:31:21 Thursday
============================

============================
[debug] Begin to login ...

[error] :.:.:.:.: Except return :.:.:.:.:
[error] Python Error: 
 Traceback (most recent call last):
  File "Actions/checkin.py", line 78, in <module>
    csrfToken = csrfToken.pop().attrib["content"]
IndexError: pop from empty list

:.:.:.:.: Finally :.:.:.:.:
[info] Notification sended at 2021-03-05 07:01:38 Friday
[info] Task Finished at 2021-03-05 07:01:38 Friday
============================

============================
[debug] Begin to login ...

[error] :.:.:.:.: Except return :.:.:.:.:
[error] Python Error: 
 Traceback (most recent call last):
  File "Actions/checkin.py", line 78, in <module>
    csrfToken = csrfToken.pop().attrib["content"]
IndexError: pop from empty list

:.:.:.:.: Finally :.:.:.:.:
[info] Notification sended at 2021-03-05 08:03:28 Friday
[info] Task Finished at 2021-03-05 08:03:28 Friday
============================

============================
[debug] Begin to login ...

[error] :.:.:.:.: Except return :.:.:.:.:
[error] Python Error: 
 Traceback (most recent call last):
  File "Actions/checkin.py", line 78, in <module>
    csrfToken = csrfToken.pop().attrib["content"]
IndexError: pop from empty list

:.:.:.:.: Finally :.:.:.:.:
[info] Notification sended at 2021-03-05 09:32:46 Friday
[info] Task Finished at 2021-03-05 09:32:46 Friday
============================

============================
[debug] Begin to login ...

[error] :.:.:.:.: Except return :.:.:.:.:
[error] Python Error: 
 Traceback (most recent call last):
  File "Actions/checkin.py", line 78, in <module>
    csrfToken = csrfToken.pop().attrib["content"]
IndexError: pop from empty list

:.:.:.:.: Finally :.:.:.:.:
[info] Notification sended at 2021-03-06 07:01:39 Saturday
[info] Task Finished at 2021-03-06 07:01:39 Saturday
============================

============================
[debug] Begin to login ...

[error] :.:.:.:.: Except return :.:.:.:.:
[error] Python Error: 
 Traceback (most recent call last):
  File "Actions/checkin.py", line 78, in <module>
    csrfToken = csrfToken.pop().attrib["content"]
IndexError: pop from empty list

:.:.:.:.: Finally :.:.:.:.:
============================
[debug] Begin to login ...

[error] :.:.:.:.: Except return :.:.:.:.:
[error] Python Error: 
 Traceback (most recent call last):
  File "Actions/checkin.py", line 78, in <module>
    csrfToken = csrfToken.pop().attrib["content"]
IndexError: pop from empty list

:.:.:.:.: Finally :.:.:.:.:
[info] Notification sended at 2021-03-06 09:31:41 Saturday
[info] Task Finished at 2021-03-06 09:31:41 Saturday
============================

============================
[debug] Begin to login ...

[error] :.:.:.:.: Except return :.:.:.:.:
[error] Python Error: 
 Traceback (most recent call last):
  File "Actions/checkin.py", line 78, in <module>
    csrfToken = csrfToken.pop().attrib["content"]
IndexError: pop from empty list

:.:.:.:.: Finally :.:.:.:.:
[info] Notification sended at 2021-03-07 07:01:30 Sunday
[info] Task Finished at 2021-03-07 07:01:30 Sunday
============================

============================
[debug] Begin to login ...

[error] :.:.:.:.: Except return :.:.:.:.:
[error] Python Error: 
 Traceback (most recent call last):
  File "Actions/checkin.py", line 78, in <module>
    csrfToken = csrfToken.pop().attrib["content"]
IndexError: pop from empty list

:.:.:.:.: Finally :.:.:.:.:
[info] Notification sended at 2021-03-07 08:03:34 Sunday
[info] Task Finished at 2021-03-07 08:03:34 Sunday
============================

============================
[debug] Begin to login ...

[error] :.:.:.:.: Except return :.:.:.:.:
[error] Python Error: 
 Traceback (most recent call last):
  File "Actions/checkin.py", line 78, in <module>
    csrfToken = csrfToken.pop().attrib["content"]
IndexError: pop from empty list

:.:.:.:.: Finally :.:.:.:.:
[info] Notification sended at 2021-03-07 09:35:03 Sunday
[info] Task Finished at 2021-03-07 09:35:03 Sunday
============================

============================
[debug] Begin to login ...

[error] :.:.:.:.: Except return :.:.:.:.:
[error] Python Error: 
 Traceback (most recent call last):
  File "Actions/checkin.py", line 78, in <module>
    csrfToken = csrfToken.pop().attrib["content"]
IndexError: pop from empty list

:.:.:.:.: Finally :.:.:.:.:
[info] Notification sended at 2021-03-08 07:01:33 Monday
[info] Task Finished at 2021-03-08 07:01:33 Monday
============================

============================
[debug] Begin to login ...

[error] :.:.:.:.: Except return :.:.:.:.:
[error] Python Error: 
 Traceback (most recent call last):
  File "Actions/checkin.py", line 78, in <module>
    csrfToken = csrfToken.pop().attrib["content"]
IndexError: pop from empty list

:.:.:.:.: Finally :.:.:.:.:
[info] Notification sended at 2021-03-08 08:03:17 Monday
[info] Task Finished at 2021-03-08 08:03:17 Monday
============================

============================
[debug] Begin to login ...

[error] :.:.:.:.: Except return :.:.:.:.:
[error] Python Error: 
 Traceback (most recent call last):
  File "Actions/checkin.py", line 78, in <module>
    csrfToken = csrfToken.pop().attrib["content"]
IndexError: pop from empty list

:.:.:.:.: Finally :.:.:.:.:
[info] Notification sended at 2021-03-08 09:33:58 Monday
[info] Task Finished at 2021-03-08 09:33:58 Monday
============================

============================
[debug] Begin to login ...

[error] :.:.:.:.: Except return :.:.:.:.:
[error] Python Error: 
 Traceback (most recent call last):
  File "Actions/checkin.py", line 78, in <module>
    csrfToken = csrfToken.pop().attrib["content"]
IndexError: pop from empty list

:.:.:.:.: Finally :.:.:.:.:
[info] Notification sended at 2021-03-09 07:01:57 Tuesday
[info] Task Finished at 2021-03-09 07:01:57 Tuesday
============================

============================
[debug] Begin to login ...

[error] :.:.:.:.: Except return :.:.:.:.:
[error] Python Error: 
 Traceback (most recent call last):
  File "Actions/checkin.py", line 78, in <module>
    csrfToken = csrfToken.pop().attrib["content"]
IndexError: pop from empty list

:.:.:.:.: Finally :.:.:.:.:
============================
[debug] Begin to login ...

[error] :.:.:.:.: Except return :.:.:.:.:
[error] Python Error: 
 Traceback (most recent call last):
  File "Actions/checkin.py", line 78, in <module>
    csrfToken = csrfToken.pop().attrib["content"]
IndexError: pop from empty list

:.:.:.:.: Finally :.:.:.:.:
[info] Notification sended at 2021-03-09 09:32:59 Tuesday
[info] Task Finished at 2021-03-09 09:32:59 Tuesday
============================

============================
[debug] Begin to login ...

[error] :.:.:.:.: Except return :.:.:.:.:
[error] Python Error: 
 Traceback (most recent call last):
  File "Actions/checkin.py", line 78, in <module>
    csrfToken = csrfToken.pop().attrib["content"]
IndexError: pop from empty list

:.:.:.:.: Finally :.:.:.:.:
[info] Notification sended at 2021-03-10 07:01:51 Wednesday
[info] Task Finished at 2021-03-10 07:01:51 Wednesday
============================

============================
[debug] Begin to login ...

[error] :.:.:.:.: Except return :.:.:.:.:
[error] Python Error: 
 Traceback (most recent call last):
  File "Actions/checkin.py", line 78, in <module>
    csrfToken = csrfToken.pop().attrib["content"]
IndexError: pop from empty list

:.:.:.:.: Finally :.:.:.:.:
[info] Notification sended at 2021-03-10 08:03:11 Wednesday
[info] Task Finished at 2021-03-10 08:03:11 Wednesday
============================

============================
[debug] Begin to login ...

[error] :.:.:.:.: Except return :.:.:.:.:
[error] Python Error: 
 Traceback (most recent call last):
  File "Actions/checkin.py", line 78, in <module>
    csrfToken = csrfToken.pop().attrib["content"]
IndexError: pop from empty list

:.:.:.:.: Finally :.:.:.:.:
[info] Notification sended at 2021-03-10 09:33:16 Wednesday
[info] Task Finished at 2021-03-10 09:33:16 Wednesday
============================

============================
[debug] Begin to login ...

[error] :.:.:.:.: Except return :.:.:.:.:
[error] Python Error: 
 Traceback (most recent call last):
  File "Actions/checkin.py", line 78, in <module>
    csrfToken = csrfToken.pop().attrib["content"]
IndexError: pop from empty list

:.:.:.:.: Finally :.:.:.:.:
[info] Notification sended at 2021-03-11 07:01:32 Thursday
[info] Task Finished at 2021-03-11 07:01:32 Thursday
============================

============================
[debug] Begin to login ...

[error] :.:.:.:.: Except return :.:.:.:.:
[error] Python Error: 
 Traceback (most recent call last):
  File "Actions/checkin.py", line 78, in <module>
    csrfToken = csrfToken.pop().attrib["content"]
IndexError: pop from empty list

:.:.:.:.: Finally :.:.:.:.:
[info] Notification sended at 2021-03-11 08:03:10 Thursday
[info] Task Finished at 2021-03-11 08:03:10 Thursday
============================

============================
[debug] Begin to login ...

[error] :.:.:.:.: Except return :.:.:.:.:
[error] Python Error: 
 Traceback (most recent call last):
  File "Actions/checkin.py", line 78, in <module>
    csrfToken = csrfToken.pop().attrib["content"]
IndexError: pop from empty list

:.:.:.:.: Finally :.:.:.:.:
[info] Notification sended at 2021-03-11 09:34:02 Thursday
[info] Task Finished at 2021-03-11 09:34:02 Thursday
============================

============================
[debug] Begin to login ...

[error] :.:.:.:.: Except return :.:.:.:.:
[error] Python Error: 
 Traceback (most recent call last):
  File "Actions/checkin.py", line 78, in <module>
    csrfToken = csrfToken.pop().attrib["content"]
IndexError: pop from empty list

:.:.:.:.: Finally :.:.:.:.:
[info] Notification sended at 2021-03-12 07:01:34 Friday
[info] Task Finished at 2021-03-12 07:01:34 Friday
============================

============================
[debug] Begin to login ...

[error] :.:.:.:.: Except return :.:.:.:.:
[error] Python Error: 
 Traceback (most recent call last):
  File "Actions/checkin.py", line 78, in <module>
    csrfToken = csrfToken.pop().attrib["content"]
IndexError: pop from empty list

:.:.:.:.: Finally :.:.:.:.:
[info] Notification sended at 2021-03-12 08:03:27 Friday
[info] Task Finished at 2021-03-12 08:03:27 Friday
============================

============================
[debug] Begin to login ...

[error] :.:.:.:.: Except return :.:.:.:.:
[error] Python Error: 
 Traceback (most recent call last):
  File "Actions/checkin.py", line 78, in <module>
    csrfToken = csrfToken.pop().attrib["content"]
IndexError: pop from empty list

:.:.:.:.: Finally :.:.:.:.:
[info] Notification sended at 2021-03-12 09:34:47 Friday
[info] Task Finished at 2021-03-12 09:34:47 Friday
============================

============================
[debug] Begin to login ...

[error] :.:.:.:.: Except return :.:.:.:.:
[error] Python Error: 
 Traceback (most recent call last):
  File "Actions/checkin.py", line 78, in <module>
    csrfToken = csrfToken.pop().attrib["content"]
IndexError: pop from empty list

:.:.:.:.: Finally :.:.:.:.:
[info] Notification sended at 2021-03-13 07:01:40 Saturday
[info] Task Finished at 2021-03-13 07:01:40 Saturday
============================

============================
[debug] Begin to login ...

[error] :.:.:.:.: Except return :.:.:.:.:
[error] Python Error: 
 Traceback (most recent call last):
  File "Actions/checkin.py", line 78, in <module>
    csrfToken = csrfToken.pop().attrib["content"]
IndexError: pop from empty list

:.:.:.:.: Finally :.:.:.:.:
============================
[debug] Begin to login ...

[error] :.:.:.:.: Except return :.:.:.:.:
[error] Python Error: 
 Traceback (most recent call last):
  File "Actions/checkin.py", line 78, in <module>
    csrfToken = csrfToken.pop().attrib["content"]
IndexError: pop from empty list

:.:.:.:.: Finally :.:.:.:.:
[info] Notification sended at 2021-03-13 09:33:17 Saturday
[info] Task Finished at 2021-03-13 09:33:17 Saturday
============================

============================
[debug] Begin to login ...

[error] :.:.:.:.: Except return :.:.:.:.:
[error] Python Error: 
 Traceback (most recent call last):
  File "Actions/checkin.py", line 78, in <module>
    csrfToken = csrfToken.pop().attrib["content"]
IndexError: pop from empty list

:.:.:.:.: Finally :.:.:.:.:
[info] Notification sended at 2021-03-14 07:01:29 Sunday
[info] Task Finished at 2021-03-14 07:01:29 Sunday
============================

============================
[debug] Begin to login ...

[error] :.:.:.:.: Except return :.:.:.:.:
[error] Python Error: 
 Traceback (most recent call last):
  File "Actions/checkin.py", line 78, in <module>
    csrfToken = csrfToken.pop().attrib["content"]
IndexError: pop from empty list

:.:.:.:.: Finally :.:.:.:.:
[info] Notification sended at 2021-03-14 08:03:20 Sunday
[info] Task Finished at 2021-03-14 08:03:20 Sunday
============================

============================
[debug] Begin to login ...

[error] :.:.:.:.: Except return :.:.:.:.:
[error] Python Error: 
 Traceback (most recent call last):
  File "Actions/checkin.py", line 78, in <module>
    csrfToken = csrfToken.pop().attrib["content"]
IndexError: pop from empty list

:.:.:.:.: Finally :.:.:.:.:
[info] Notification sended at 2021-03-14 09:37:00 Sunday
[info] Task Finished at 2021-03-14 09:37:00 Sunday
============================

============================
[debug] Begin to login ...

[error] :.:.:.:.: Except return :.:.:.:.:
[error] Python Error: 
 Traceback (most recent call last):
  File "Actions/checkin.py", line 78, in <module>
    csrfToken = csrfToken.pop().attrib["content"]
IndexError: pop from empty list

:.:.:.:.: Finally :.:.:.:.:
[info] Notification sended at 2021-03-15 07:01:30 Monday
[info] Task Finished at 2021-03-15 07:01:30 Monday
============================

============================
[debug] Begin to login ...

[error] :.:.:.:.: Except return :.:.:.:.:
[error] Python Error: 
 Traceback (most recent call last):
  File "Actions/checkin.py", line 78, in <module>
    csrfToken = csrfToken.pop().attrib["content"]
IndexError: pop from empty list

:.:.:.:.: Finally :.:.:.:.:
